Workbook

Sheet Gráficos
K2: La industria manufacturera uruguaya muestra una reducción sostenida del apalancamiento: el pasivo no corriente cayó del 46,5% al 18,3% del capital total entre 2006 y 2024, mientras que los intereses disminuyeron del 11,2% al 7,9% de la ganancia. Esto se explica por el mayor crecimiento del stock de capital, cuyo índice alcanzó 457,2 en 2024, frente a 161,0 del endeudamiento.
K15: La rentabilidad sobre el patrimonio neto presenta valores muy elevados —con un máximo de 1.458% en 2014 y 609% en 2024—, lo que implica un patrimonio neto reducido. Al descontar la inversión en capital fijo, la tasa de ganancia registra un promedio de apenas 3%, con un mínimo de −31% en 2015, un máximo de 21% en 2018 y una recuperación hasta 7% en 2024. En conjunto, el menor endeudamiento convive con una rentabilidad efectiva baja y fuertemente cíclica.

Sheet Fuentes
B2: Endeudamiento con el sistema financiero nacional. No externo. Son saldos de créditos con el sistema financiero bancario local + endeudamiento a través de obligaciones nacionales a nivel local también.
B4: Link
B5: https://www.ciu.com.uy/wp-content/uploads/2026/04/Endeudamiento-industrial-N30_2-_Sem_2025.pdf

Sheet TG PN
B1: corrientes | C1: corrientes | D1: constantes | E1: corrientes | F1: corrientes | G1: Mill USD | H1: Mill USD | J1: 1870-1912: Willebald et al (15); +13: PHES -Silvana Maubrigades | L1: Mill USD | M1: Mill USD | N1: Mill USD | O1: Mill USD | P1: Mill USD | Q1: Mill USD | S1: Mill USD | AE1: Millones de pesos | AF1: Millones de pesos | AG1: Millones de pesos
B2: capital_total_adelantado | C2: stock_capital | D2: capital_total_adelantado | E2: Ganancia desp de impuestos | F2: fbcf | G2: Endeudamiento Industrial | H2: Intereses pagos por la industria | I2: intereses pagos por eaae, ajuste c/ microdatos (90%) | J2: Tipo de cambio libre | K2: TC Paridad c/prod no agraria | L2: capital_total_adelantado | M2: stock_capital | N2: Ganancia | O2: FBCF | P2: Ganancia desp de intereses pagados | Q2: Ganancia desp de impuestos e intereses pagados, menos la FBCF | R2: % de los intereses respecto de la ganancia | S2: Patrimonio neto (Aprox.) | T2: stock de capital menos endeudamiento | U2: Pasivo no corriente / KTA | V2: Endeudamiento (2006 = 100) | W2: stock_capital (2006 = 100) | X2: Tasa de ganancia manuf | Y2: Tasa de ganancia capital propio | Z2: Tasa de ganancia capital propio desp de FBCF | AA2: Tasa de ganancia PN (sobre capital fijo menos endeudamiento) | AB2: Promedio | AE2: Intereses x TC | AF2: Intereses por TCP | AG2: Abaratamiento por tc. Diferencia intereses | AH2: Abaratamiento sobre ganancia desp de impuestos
A3: 2001 | B3: 3.9864242e+10 | C3: 28622363000 | D3: 2.3946122e+11 | E3: 5.0869177e+09 | F3: 3539644000 | J3: 13.408852 | K3: 19.078999 | L3: =B3/J3/1000000 -> 2972.9795 | M3: =C3/J3/1000000 -> 2134.5871 | N3: =E3/J3/1000000 -> 379.37011 | O3: =F3/J3/1000000 -> 263.97815 | W3: =M3/M$8*100 -> 89.859415 | X3: ='rama-C'!AD2 -> 0.12760603
A4: 2002 | B4: 5.0476907e+10 | D4: 2.0999612e+11 | E4: 1.348539e+10 | J4: 21.587268 | K4: 22.652647 | L4: =B4/J4/1000000 -> 2338.2721 | N4: =E4/J4/1000000 -> 624.69183 | X4: ='rama-C'!AD3 -> 0.26715959
A5: 2003 | B5: 6.5662459e+10 | C5: 48103564060 | D5: 1.9856951e+11 | E5: 1.2655823e+10 | F5: 6899547696 | J5: 28.369939 | K5: 26.367312 | L5: =B5/J5/1000000 -> 2314.5083 | M5: =C5/J5/1000000 -> 1695.5822 | N5: =E5/J5/1000000 -> 446.09976 | O5: =F5/J5/1000000 -> 243.19924 | W5: =M5/M$8*100 -> 71.378686 | X5: ='rama-C'!AD4 -> 0.19274062
A6: 2004 | B6: 7.2889933e+10 | C6: 50525577181 | D6: 2.497745e+11 | E6: 1.9229598e+10 | F6: 6396127195 | J6: 28.703792 | K6: 29.122846 | L6: =B6/J6/1000000 -> 2539.3834 | M6: =C6/J6/1000000 -> 1760.2405 | N6: =E6/J6/1000000 -> 669.93233 | O6: =F6/J6/1000000 -> 222.83213 | W6: =M6/M$8*100 -> 74.100597 | X6: ='rama-C'!AD5 -> 0.26381693
A7: 2005 | B7: 7.5872497e+10 | C7: 52418214093 | D7: 3.0450928e+11 | E7: 1.735402e+10 | F7: 6464007473 | J7: 24.478579 | K7: 28.325217 | L7: =B7/J7/1000000 -> 3099.5466 | M7: =C7/J7/1000000 -> 2141.3912 | N7: =E7/J7/1000000 -> 708.94719 | O7: =F7/J7/1000000 -> 264.06792 | W7: =M7/M$8*100 -> 90.145845 | X7: ='rama-C'!AD6 -> 0.22872609
A8: 2006 | B8: 8.056767e+10 | C8: 5.7185677e+10 | D8: 2.7392317e+11 | E8: 1.7995065e+10 | F8: 6.5161369e+09 | G8: 1556.8148 | H8: 83.75346 | I8: =H8*0.9 -> 75.378114 | J8: 24.073374 | K8: 29.954262 | L8: =B8/J8/1000000 -> 3346.7544 | M8: =C8/J8/1000000 -> 2375.4741 | N8: =E8/J8/1000000 -> 747.50904 | O8: =F8/J8/1000000 -> 270.67817 | P8: =N8-H8 -> 663.75558 | Q8: =P8-O8 -> 393.0774 | R8: =H8/N8 -> 0.11204341 | S8: =L8-G8 -> 1789.9396 | T8: =M8-G8 -> 818.6593 | U8: =G8/L8 -> 0.46517152 | V8: =G8/G$8*100 -> 100 | W8: =M8/M$8*100 -> 100 | X8: ='rama-C'!AD7 -> 0.22335342 | AE8: =$I8*J8 -> 1814.6055 | AF8: =$I8*K8 -> 2257.8958 | AG8: =AF8-AE8 -> 443.29025 | AH8: =AG8/(E8/1000000) -> 0.02463399
A9: 2007 | B9: 1.1812089e+11 | C9: 8.8288213e+10 | D9: 3.2429228e+11 | E9: 2.41105e+10 | F9: 1.735929e+10 | G9: 1737.3081 | H9: 89.035722 | I9: =H9*0.9 -> 80.13215 | J9: 23.471036 | K9: 30.861639 | L9: =B9/J9/1000000 -> 5032.6237 | M9: =C9/J9/1000000 -> 3761.5814 | N9: =E9/J9/1000000 -> 1027.2448 | O9: =F9/J9/1000000 -> 739.60474 | P9: =N9-H9 -> 938.20909 | Q9: =P9-O9 -> 198.60435 | R9: =H9/N9 -> 0.086674297 | S9: =L9-G9 -> 3295.3157 | T9: =M9-G9 -> 2024.2734 | U9: =G9/L9 -> 0.34520921 | V9: =G9/G$8*100 -> 111.59375 | W9: =M9/M$8*100 -> 158.35076 | X9: ='rama-C'!AD8 -> 0.20411715 | Y9: =S9/P9 -> 3.5123467 | Z9: =Q9/S9 -> 0.060268688 | AA9: =P9/T9 -> 0.46347945 | AB9: =AVERAGE(Z$9:Z$26) -> 0.034243627 | AE9: =$I9*J9 -> 1880.7846 | AF9: =$I9*K9 -> 2473.0095 | AG9: =AF9-AE9 -> 592.22491 | AH9: =AG9/(E9/1000000) -> 0.024562946
A10: 2008 | B10: 1.4476563e+11 | C10: 1.0797121e+11 | D10: 3.496873e+11 | E10: 2.6698283e+10 | F10: 1.7442926e+10 | G10: 1785.2371 | H10: 92.377722 | I10: =H10*0.9 -> 83.139949 | J10: 20.949345 | K10: 30.471964 | L10: =B10/J10/1000000 -> 6910.2702 | M10: =C10/J10/1000000 -> 5153.9183 | N10: =E10/J10/1000000 -> 1274.4209 | O10: =F10/J10/1000000 -> 832.62394 | P10: =N10-H10 -> 1182.0432 | Q10: =P10-O10 -> 349.41924 | R10: =H10/N10 -> 0.072486038 | S10: =L10-G10 -> 5125.0331 | T10: =M10-G10 -> 3368.6811 | U10: =G10/L10 -> 0.25834549 | V10: =G10/G$8*100 -> 114.67241 | W10: =M10/M$8*100 -> 216.96377 | X10: ='rama-C'!AD9 -> 0.18442418 | Y10: =S10/P10 -> 4.335741 | Z10: =Q10/S10 -> 0.068178923 | AA10: =P10/T10 -> 0.35089197 | AB10: =AVERAGE(Z$9:Z$26) -> 0.034243627 | AE10: =$I10*J10 -> 1741.7275 | AF10: =$I10*K10 -> 2533.4375 | AG10: =AF10-AE10 -> 791.71006 | AH10: =AG10/(E10/1000000) -> 0.029653969
A11: 2009 | B11: 1.2763899e+11 | C11: 9.3192118e+10 | D11: 3.3559366e+11 | E11: 1.801868e+10 | F11: 7.9610854e+09 | G11: 1666.6448 | H11: 93.63592 | I11: =H11*0.9 -> 84.272328 | J11: 22.567971 | K11: 32.276463 | L11: =B11/J11/1000000 -> 5655.7583 | M11: =C11/J11/1000000 -> 4129.3973 | N11: =E11/J11/1000000 -> 798.41826 | O11: =F11/J11/1000000 -> 352.76035 | P11: =N11-H11 -> 704.78234 | Q11: =P11-O11 -> 352.02199 | R11: =H11/N11 -> 0.11727678 | S11: =L11-G11 -> 3989.1135 | T11: =M11-G11 -> 2462.7524 | U11: =G11/L11 -> 0.29468106 | V11: =G11/G$8*100 -> 107.05479 | W11: =M11/M$8*100 -> 173.83466 | X11: ='rama-C'!AD10 -> 0.14116909 | Y11: =S11/P11 -> 5.6600644 | Z11: =Q11/S11 -> 0.088245669 | AA11: =P11/T11 -> 0.28617669 | AB11: =AVERAGE(Z$9:Z$26) -> 0.034243627 | AE11: =$I11*J11 -> 1901.8555 | AF11: =$I11*K11 -> 2720.0127 | AG11: =AF11-AE11 -> 818.15722 | AH11: =AG11/(E11/1000000) -> 0.045406057
A12: 2010 | B12: 1.3817191e+11 | C12: 9.973781e+10 | D12: 4.0692949e+11 | E12: 2.4477634e+10 | F12: 1.0581329e+10 | G12: 1792.8303 | H12: 74.52889 | I12: =H12*0.9 -> 67.076001 | J12: 20.059238 | K12: 32.828748 | L12: =B12/J12/1000000 -> 6888.1932 | M12: =C12/J12/1000000 -> 4972.1635 | N12: =E12/J12/1000000 -> 1220.2674 | O12: =F12/J12/1000000 -> 527.50402 | P12: =N12-H12 -> 1145.7385 | Q12: =P12-O12 -> 618.2345 | R12: =H12/N12 -> 0.061075867 | S12: =L12-G12 -> 5095.3629 | T12: =M12-G12 -> 3179.3332 | U12: =G12/L12 -> 0.26027584 | V12: =G12/G$8*100 -> 115.16015 | W12: =M12/M$8*100 -> 209.31247 | X12: ='rama-C'!AD11 -> 0.17715348 | Y12: =S12/P12 -> 4.4472302 | Z12: =Q12/S12 -> 0.12133277 | AA12: =P12/T12 -> 0.3603707 | AB12: =AVERAGE(Z$9:Z$26) -> 0.034243627 | AE12: =$I12*J12 -> 1345.4935 | AF12: =$I12*K12 -> 2202.0211 | AG12: =AF12-AE12 -> 856.52767 | AH12: =AG12/(E12/1000000) -> 0.034992257
A13: 2011 | B13: 1.6459051e+11 | D13: 3.9455398e+11 | E13: 1.5603516e+10 | G13: 2051.7036 | H13: 85.105635 | I13: =H13*0.9 -> 76.595071 | J13: 19.314209 | K13: 34.651025 | L13: =B13/J13/1000000 -> 8521.7321 | N13: =E13/J13/1000000 -> 807.87756 | P13: =N13-H13 -> 722.77192 | Q13: =P13-O13 -> 722.77192 | R13: =H13/N13 -> 0.10534472 | S13: =L13-G13 -> 6470.0284 | U13: =G13/L13 -> 0.24076134 | V13: =G13/G$8*100 -> 131.78855 | X13: ='rama-C'!AD12 -> 0.094802037 | Y13: =S13/P13 -> 8.9516876 | Z13: =Q13/S13 -> 0.11171078 | AB13: =AVERAGE(Z$9:Z$26) -> 0.034243627 | AE13: =$I13*J13 -> 1479.3732 | AF13: =$I13*K13 -> 2654.0977 | AG13: =AF13-AE13 -> 1174.7245 | AH13: =AG13/(E13/1000000) -> 0.075285886
A14: 2012 | B14: 1.6778489e+11 | C14: 1.1807022e+11 | D14: 3.9509125e+11 | E14: 1.2653049e+10 | F14: 1.7144628e+10 | G14: 2252.2035 | H14: 102.14219 | I14: =H14*0.9 -> 91.92797 | J14: 20.310164 | K14: 35.243068 | L14: =B14/J14/1000000 -> 8261.1292 | M14: =C14/J14/1000000 -> 5813.3565 | N14: =E14/J14/1000000 -> 622.99097 | O14: =F14/J14/1000000 -> 844.14033 | P14: =N14-H14 -> 520.84878 | Q14: =P14-O14 -> -323.29155 | R14: =H14/N14 -> 0.16395453 | S14: =L14-G14 -> 6008.9257 | T14: =M14-G14 -> 3561.153 | U14: =G14/L14 -> 0.27262659 | V14: =G14/G$8*100 -> 144.6674 | W14: =M14/M$8*100 -> 244.72405 | X14: ='rama-C'!AD13 -> 0.075412326 | Y14: =S14/P14 -> 11.536795 | Z14: =Q14/S14 -> -0.053801888 | AA14: =P14/T14 -> 0.14625846 | AB14: =AVERAGE(Z$9:Z$26) -> 0.034243627 | AE14: =$I14*J14 -> 1867.0721 | AF14: =$I14*K14 -> 3239.8237 | AG14: =AF14-AE14 -> 1372.7515 | AH14: =AG14/(E14/1000000) -> 0.10849176
A15: 2013 | B15: 1.8349807e+11 | C15: 1.3030327e+11 | D15: 4.1091262e+11 | E15: 1.2278747e+10 | F15: 2.8790673e+10 | G15: 2329.9271 | H15: 115.22407 | I15: =H15*0.9 -> 103.70167 | J15: 20.481618 | K15: 35.991435 | L15: =B15/J15/1000000 -> 8959.159 | M15: =C15/J15/1000000 -> 6361.9616 | N15: =E15/J15/1000000 -> 599.50085 | O15: =F15/J15/1000000 -> 1405.6835 | P15: =N15-H15 -> 484.27678 | Q15: =P15-O15 -> -921.40674 | R15: =H15/N15 -> 0.19220002 | S15: =L15-G15 -> 6629.2319 | T15: =M15-G15 -> 4032.0346 | U15: =G15/L15 -> 0.26006092 | V15: =G15/G$8*100 -> 149.65987 | W15: =M15/M$8*100 -> 267.81861 | X15: ='rama-C'!AD14 -> 0.066914858 | Y15: =S15/P15 -> 13.688932 | Z15: =Q15/S15 -> -0.13899148 | AA15: =P15/T15 -> 0.1201073 | AB15: =AVERAGE(Z$9:Z$26) -> 0.034243627 | AE15: =$I15*J15 -> 2123.9779 | AF15: =$I15*K15 -> 3732.3718 | AG15: =AF15-AE15 -> 1608.3939 | AH15: =AG15/(E15/1000000) -> 0.13099006
A16: 2014 | B16: 2.5937714e+11 | C16: 1.9842942e+11 | D16: 4.5420126e+11 | E16: 1.7067828e+10 | F16: 7.8176629e+10 | G16: 2179.4861 | H16: 118.36466 | I16: =H16*0.9 -> 106.5282 | J16: 23.246061 | K16: 38.372773 | L16: =B16/J16/1000000 -> 11157.896 | M16: =C16/J16/1000000 -> 8536.0448 | N16: =E16/J16/1000000 -> 734.22452 | O16: =F16/J16/1000000 -> 3363.0054 | P16: =N16-H16 -> 615.85985 | Q16: =P16-O16 -> -2747.1456 | R16: =H16/N16 -> 0.16121045 | S16: =L16-G16 -> 8978.4103 | T16: =M16-G16 -> 6356.5586 | U16: =G16/L16 -> 0.19533127 | V16: =G16/G$8*100 -> 139.99649 | W16: =M16/M$8*100 -> 359.34068 | X16: ='rama-C'!AD15 -> 0.06580313 | Y16: =S16/P16 -> 14.578658 | Z16: =Q16/S16 -> -0.30597238 | AA16: =P16/T16 -> 0.096885735 | AB16: =AVERAGE(Z$9:Z$26) -> 0.034243627 | AE16: =$I16*J16 -> 2476.361 | AF16: =$I16*K16 -> 4087.7823 | AG16: =AF16-AE16 -> 1611.4214 | AH16: =AG16/(E16/1000000) -> 0.094412796
A17: 2015 | B17: 2.7046004e+11 | C17: 2.0781379e+11 | D17: 4.546719e+11 | E17: 2.4840445e+10 | F17: 2.6806672e+10 | G17: 2377.4684 | H17: 110.4421 | I17: =H17*0.9 -> 99.397894 | J17: 27.327226 | K17: 41.149156 | L17: =B17/J17/1000000 -> 9897.091 | M17: =C17/J17/1000000 -> 7604.6429 | N17: =E17/J17/1000000 -> 908.99988 | O17: =F17/J17/1000000 -> 980.9511 | P17: =N17-H17 -> 798.55777 | Q17: =P17-O17 -> -182.39333 | R17: =H17/N17 -> 0.12149848 | S17: =L17-G17 -> 7519.6227 | T17: =M17-G17 -> 5227.1745 | U17: =G17/L17 -> 0.2402189 | V17: =G17/G$8*100 -> 152.71363 | W17: =M17/M$8*100 -> 320.13158 | X17: ='rama-C'!AD16 -> 0.091845157 | Y17: =S17/P17 -> 9.4165042 | Z17: =Q17/S17 -> -0.024255649 | AA17: =P17/T17 -> 0.15277044 | AB17: =AVERAGE(Z$9:Z$26) -> 0.034243627 | AE17: =$I17*J17 -> 2716.2687 | AF17: =$I17*K17 -> 4090.1395 | AG17: =AF17-AE17 -> 1373.8707 | AH17: =AG17/(E17/1000000) -> 0.055307815
A18: 2016 | B18: 2.8330238e+11 | C18: 2.188245e+11 | D18: 4.5819744e+11 | E18: 1.9680939e+10 | F18: 1.7409372e+10 | G18: 2353.9156 | H18: 116.70317 | I18: =H18*0.9 -> 105.03285 | J18: 30.1626 | K18: 44.043941 | L18: =B18/J18/1000000 -> 9392.5052 | M18: =C18/J18/1000000 -> 7254.8288 | N18: =E18/J18/1000000 -> 652.49479 | O18: =F18/J18/1000000 -> 577.18405 | P18: =N18-H18 -> 535.79162 | Q18: =P18-O18 -> -41.392433 | R18: =H18/N18 -> 0.17885686 | S18: =L18-G18 -> 7038.5896 | T18: =M18-G18 -> 4900.9132 | U18: =G18/L18 -> 0.25061637 | V18: =G18/G$8*100 -> 151.20075 | W18: =M18/M$8*100 -> 305.40551 | X18: ='rama-C'!AD17 -> 0.069469729 | Y18: =S18/P18 -> 13.136804 | Z18: =Q18/S18 -> -0.0058807851 | AA18: =P18/T18 -> 0.10932486 | AB18: =AVERAGE(Z$9:Z$26) -> 0.034243627 | AE18: =$I18*J18 -> 3168.0639 | AF18: =$I18*K18 -> 4626.0608 | AG18: =AF18-AE18 -> 1457.9969 | AH18: =AG18/(E18/1000000) -> 0.07408167
A19: 2017 | B19: 2.7320664e+11 | C19: 2.097731e+11 | D19: 4.5688633e+11 | E19: 4.7598175e+10 | F19: 1.703624e+10 | G19: 2159.4332 | H19: 109.68601 | I19: =H19*0.9 -> 98.717406 | J19: 28.65 | K19: 44.520022 | L19: =B19/J19/1000000 -> 9536.0083 | M19: =C19/J19/1000000 -> 7321.9231 | N19: =E19/J19/1000000 -> 1661.3674 | O19: =F19/J19/1000000 -> 594.63316 | P19: =N19-H19 -> 1551.6813 | Q19: =P19-O19 -> 957.04819 | R19: =H19/N19 -> 0.066021525 | S19: =L19-G19 -> 7376.5751 | T19: =M19-G19 -> 5162.4899 | U19: =G19/L19 -> 0.22645044 | V19: =G19/G$8*100 -> 138.70842 | W19: =M19/M$8*100 -> 308.22997 | X19: ='rama-C'!AD18 -> 0.17422042 | Y19: =S19/P19 -> 4.7539239 | Z19: =Q19/S19 -> 0.12974154 | AA19: =P19/T19 -> 0.3005684 | AB19: =AVERAGE(Z$9:Z$26) -> 0.034243627 | AE19: =$I19*J19 -> 2828.2537 | AF19: =$I19*K19 -> 4394.9011 | AG19: =AF19-AE19 -> 1566.6474 | AH19: =AG19/(E19/1000000) -> 0.032914023
A20: 2018 | B20: 303469927276 | C20: 2.3094465e+11 | D20: 4.6660865e+11 | E20: 7.3700681e+10 | F20: 2.1403884e+10 | G20: 2408.2765 | H20: 118.23441 | I20: =H20*0.9 -> 106.41097 | J20: 30.77 | K20: 47.58936 | L20: =B20/J20/1000000 -> 9862.5261 | M20: =C20/J20/1000000 -> 7505.5136 | N20: =E20/J20/1000000 -> 2395.2123 | O20: =F20/J20/1000000 -> 695.60883 | P20: =N20-H20 -> 2276.9778 | Q20: =P20-O20 -> 1581.369 | R20: =H20/N20 -> 0.049362813 | S20: =L20-G20 -> 7454.2496 | T20: =M20-G20 -> 5097.2371 | U20: =G20/L20 -> 0.24418455 | V20: =G20/G$8*100 -> 154.69255 | W20: =M20/M$8*100 -> 315.95855 | X20: ='rama-C'!AD19 -> 0.24285992 | Y20: =S20/P20 -> 3.2737471 | Z20: =Q20/S20 -> 0.21214329 | AA20: =P20/T20 -> 0.44670824 | AB20: =AVERAGE(Z$9:Z$26) -> 0.034243627 | AE20: =$I20*J20 -> 3274.2656 | AF20: =$I20*K20 -> 5064.0301 | AG20: =AF20-AE20 -> 1789.7645 | AH20: =AG20/(E20/1000000) -> 0.024284232
A21: 2019 | B21: 3.3849056e+11 | C21: 259048160897 | D21: 4.7965711e+11 | E21: 5.7159846e+10 | F21: 30759048024 | G21: 2177.6592 | H21: 123.64706 | I21: =H21*0.9 -> 111.28236 | J21: 35.3 | K21: 50.391059 | L21: =B21/J21/1000000 -> 9588.9677 | M21: =C21/J21/1000000 -> 7338.4748 | N21: =E21/J21/1000000 -> 1619.2591 | O21: =F21/J21/1000000 -> 871.36113 | P21: =N21-H21 -> 1495.612 | Q21: =P21-O21 -> 624.25089 | R21: =H21/N21 -> 0.076360271 | S21: =L21-G21 -> 7411.3085 | T21: =M21-G21 -> 5160.8157 | U21: =G21/L21 -> 0.22710048 | V21: =G21/G$8*100 -> 139.87914 | W21: =M21/M$8*100 -> 308.92674 | X21: ='rama-C'!AD20 -> 0.16886688 | Y21: =S21/P21 -> 4.9553684 | Z21: =Q21/S21 -> 0.084229511 | AA21: =P21/T21 -> 0.28980148 | AB21: =AVERAGE(Z$9:Z$26) -> 0.034243627 | AE21: =$I21*J21 -> 3928.2672 | AF21: =$I21*K21 -> 5607.6358 | AG21: =AF21-AE21 -> 1679.3686 | AH21: =AG21/(E21/1000000) -> 0.029380216
A22: 2020 | B22: 3.762764e+11 | C22: 2.963226e+11 | D22: 4.4815014e+11 | E22: 5.5200295e+10 | F22: 4.094156e+10 | G22: 2172.8074 | H22: 106.45435 | I22: =H22*0.9 -> 95.808915 | J22: 42 | K22: 57.605681 | L22: =B22/J22/1000000 -> 8958.9618 | M22: =C22/J22/1000000 -> 7055.3 | N22: =E22/J22/1000000 -> 1314.2927 | O22: =F22/J22/1000000 -> 974.79905 | P22: =N22-H22 -> 1207.8384 | Q22: =P22-O22 -> 233.03935 | R22: =H22/N22 -> 0.080997442 | S22: =L22-G22 -> 6786.1544 | T22: =M22-G22 -> 4882.4926 | U22: =G22/L22 -> 0.24252893 | V22: =G22/G$8*100 -> 139.56749 | W22: =M22/M$8*100 -> 297.00597 | X22: ='rama-C'!AD21 -> 0.14670146 | Y22: =S22/P22 -> 5.6184291 | Z22: =Q22/S22 -> 0.034340414 | AA22: =P22/T22 -> 0.24738151 | AB22: =AVERAGE(Z$9:Z$26) -> 0.034243627 | AE22: =$I22*J22 -> 4023.9745 | AF22: =$I22*K22 -> 5519.1378 | AG22: =AF22-AE22 -> 1495.1634 | AH22: =AG22/(E22/1000000) -> 0.027086148
A23: 2021 | B23: 4.6969871e+11 | C23: 3.7719399e+11 | D23: 4.5759101e+11 | E23: 1.0933949e+11 | F23: 8.3942984e+10 | G23: 2232.9524 | H23: 86.973256 | I23: =H23*0.9 -> 78.27593 | J23: 43.56 | K23: 58.976208 | L23: =B23/J23/1000000 -> 10782.799 | M23: =C23/J23/1000000 -> 8659.1824 | N23: =E23/J23/1000000 -> 2510.0893 | O23: =F23/J23/1000000 -> 1927.0657 | P23: =N23-H23 -> 2423.116 | Q23: =P23-O23 -> 496.05026 | R23: =H23/N23 -> 0.034649468 | S23: =L23-G23 -> 8549.8463 | T23: =M23-G23 -> 6426.23 | U23: =G23/L23 -> 0.20708468 | V23: =G23/G$8*100 -> 143.43083 | W23: =M23/M$8*100 -> 364.52438 | X23: ='rama-C'!AD22 -> 0.23278643 | Y23: =S23/P23 -> 3.5284511 | Z23: =Q23/S23 -> 0.058018617 | AA23: =P23/T23 -> 0.37706649 | AB23: =AVERAGE(Z$9:Z$26) -> 0.034243627 | AE23: =$I23*J23 -> 3409.6995 | AF23: =$I23*K23 -> 4616.4176 | AG23: =AF23-AE23 -> 1206.718 | AH23: =AG23/(E23/1000000) -> 0.011036434
A24: 2022 | B24: 5.074139e+11 | C24: 3.9260348e+11 | D24: 4.5646201e+11 | E24: 1.1087673e+11 | F24: 6.9687014e+10 | G24: 2453.2461 | H24: 113.81053 | I24: =H24*0.9 -> 102.42947 | J24: 41.3 | K24: 58.134197 | L24: =B24/J24/1000000 -> 12286.051 | M24: =C24/J24/1000000 -> 9506.1375 | N24: =E24/J24/1000000 -> 2684.6666 | O24: =F24/J24/1000000 -> 1687.3369 | P24: =N24-H24 -> 2570.8561 | Q24: =P24-O24 -> 883.51917 | R24: =H24/N24 -> 0.042392797 | S24: =L24-G24 -> 9832.8047 | T24: =M24-G24 -> 7052.8914 | U24: =G24/L24 -> 0.19967735 | V24: =G24/G$8*100 -> 157.58111 | W24: =M24/M$8*100 -> 400.17853 | X24: ='rama-C'!AD23 -> 0.21851339 | Y24: =S24/P24 -> 3.82472 | Z24: =Q24/S24 -> 0.089854237 | AA24: =P24/T24 -> 0.36451094 | AB24: =AVERAGE(Z$9:Z$26) -> 0.034243627 | AE24: =$I24*J24 -> 4230.3373 | AF24: =$I24*K24 -> 5954.6552 | AG24: =AF24-AE24 -> 1724.3179 | AH24: =AG24/(E24/1000000) -> 0.015551667
A25: 2023 | B25: 5.1091334e+11 | C25: 4.0246279e+11 | D25: 4.658893e+11 | E25: 7.1043588e+10 | F25: 5.6457789e+10 | G25: 2596.6553 | H25: 160.27276 | I25: =H25*0.9 -> 144.24548 | J25: 38.695 | K25: 60.006461 | L25: =B25/J25/1000000 -> 13203.601 | M25: =C25/J25/1000000 -> 10400.899 | N25: =E25/J25/1000000 -> 1835.9888 | O25: =F25/J25/1000000 -> 1459.0461 | P25: =N25-H25 -> 1675.7161 | Q25: =P25-O25 -> 216.67 | R25: =H25/N25 -> 0.087295061 | S25: =L25-G25 -> 10606.946 | T25: =M25-G25 -> 7804.2438 | U25: =G25/L25 -> 0.19666266 | V25: =G25/G$8*100 -> 166.79282 | W25: =M25/M$8*100 -> 437.84519 | X25: ='rama-C'!AD24 -> 0.13905213 | Y25: =S25/P25 -> 6.3297988 | Z25: =Q25/S25 -> 0.020427181 | AA25: =P25/T25 -> 0.21471857 | AB25: =AVERAGE(Z$9:Z$26) -> 0.034243627 | AE25: =$I25*J25 -> 5581.5789 | AF25: =$I25*K25 -> 8655.6609 | AG25: =AF25-AE25 -> 3074.082 | AH25: =AG25/(E25/1000000) -> 0.043270364
A26: 2024 | B26: 5.5096522e+11 | C26: 4.3696596e+11 | D26: 4.8398942e+11 | E26: 8.0163643e+10 | F26: 4.3801058e+10 | G26: 2506.69 | H26: 156.51051 | I26: =H26*0.9 -> 140.85946 | J26: 40.235 | K26: 61.848214 | L26: =B26/J26/1000000 -> 13693.68 | M26: =C26/J26/1000000 -> 10860.344 | N26: =E26/J26/1000000 -> 1992.3858 | O26: =F26/J26/1000000 -> 1088.6307 | P26: =N26-H26 -> 1835.8753 | Q26: =P26-O26 -> 747.24456 | R26: =H26/N26 -> 0.078554317 | S26: =L26-G26 -> 11186.99 | T26: =M26-G26 -> 8353.6544 | U26: =G26/L26 -> 0.18305452 | V26: =G26/G$8*100 -> 161.01402 | W26: =M26/M$8*100 -> 457.18639 | X26: ='rama-C'!AD25 -> 0.14549674 | Y26: =S26/P26 -> 6.0935458 | Z26: =Q26/S26 -> 0.066795854 | AA26: =P26/T26 -> 0.21976912 | AB26: =AVERAGE(Z$9:Z$26) -> 0.034243627 | AE26: =$I26*J26 -> 5667.4802 | AF26: =$I26*K26 -> 8711.9058 | AG26: =AF26-AE26 -> 3044.4256 | AH26: =AG26/(E26/1000000) -> 0.037977635
A27: 2025 | G27: 2704.0963 | H27: 144.46263 | I27: =H27*0.9 -> 130.01636 | J27: 41.08 | K27: 62.865715

Sheet metodología
A1: seccion_contenido | B1: nombre | C1: tipo | D1: aplica_en | E1: definicion | F1: fuente_formula
A2: estructura_libro | B2: metodología | C2: hoja | D2: Libro completo | E2: Referencia de lectura del archivo: describe las hojas y el diccionario de variables. | F2: Construida por el postproceso R.
A3: estructura_libro | B3: eaae | C3: hoja | D3: Panel base | E3: Panel completo con unidad año por sección CIIU homologada. | F3: CSV fechado del panel EAAE.
A4: estructura_libro | B4: rama-C | C4: hoja | D4: Panel base | E4: Subconjunto del panel para la rama industrial, sección C. | F4: Filtro seccion == C.
A5: estructura_libro | B5: check-calidad-C | C5: hoja | D5: Validación | E5: Indicadores anuales de control para la rama industrial. | F5: Derivada del panel rama-C.
A6: estructura_libro | B6: economia_total | C6: hoja | D6: Panel base | E6: Agregado anual de todas las secciones del panel. | F6: Suma de variables aditivas por año.
A7: estructura_libro | B7: check-calidad-total | C7: hoja | D7: Validación | E7: Indicadores anuales de control para la economía total. | F7: Derivada de economia_total.
A8: estructura_libro | B8: resultados-total-corrientes | C8: hoja | D8: Resultados | E8: Insumos y variables calculadas para economía total en valores corrientes. | F8: Cálculos propios desde economia_total.
A9: estructura_libro | B9: resultados-industrial-corrientes | C9: hoja | D9: Resultados | E9: Insumos y variables calculadas para la rama industrial en valores corrientes. | F9: Cálculos propios desde rama-C.
A10: estructura_libro | B10: resultados-total-constante | C10: hoja | D10: Resultados | E10: Insumos y variables calculadas para economía total en precios de 2005. | F10: Deflacta corrientes con índices Oyanthabal.
A11: estructura_libro | B11: resultados-industrial-constante | C11: hoja | D11: Resultados | E11: Insumos y variables calculadas para industria en precios de 2005. | F11: Deflacta corrientes con índices Oyanthabal.
A12: estructura_libro | B12: resultados-total-var-pct | C12: hoja | D12: Resultados | E12: Variación porcentual interanual de los resultados constantes de economía total. | F12: (x[t] / x[t-1] - 1) * 100.
... A64: diccionario_variables | B64: *_ind_2005 | C64: transformación | D64: Hojas resultados-*-ind-2005 | E64: Sufijo de variables expresadas como índice con base 2005=1. | F64: Encadenamiento desde variaciones interanuales.

Sheet eaae
A1: anno | B1: seccion | C1: epoca | D1: ciiu_version | E1: vbp_pp | F1: vbp_pb | G1: vab_pp | H1: vab_pb | I1: vab_pb_estimado | J1: consumo_intermedio_estimado | K1: capital_circulante_constante_adelantado | L1: remuneraciones | M1: capital_variable_adelantado | N1: puestos_trabajo | O1: n_empresas | P1: fbcf | Q1: fbkf_maq_eq | R1: adquisiciones_importadas | S1: adquisiciones_origen_importado | T1: importaciones_maquinaria | U1: consumo_capital_fijo | V1: impuestos_netos | W1: stock_capital | X1: stock_capital_imputado | Y1: capital_total_adelantado | Z1: excedente_bruto | AA1: part_salarial | AB1: productividad
A2: 2001 | B2: C | C2: 1 | D2: Rev.3 | E2: 89240215000 | G2: 32030854000 | I2: 2.6506273e+10 | J2: 6.2733942e+10 | K2: 9.5051428e+09 | L2: 11462459000 | M2: 1.7367362e+09 | N2: 113817 | O2: 12367 | P2: 3539644000 | Q2: 2057120000 | R2: 1075519000 | U2: 3127411000 | V2: 6829485000 | W2: 28622363000 | X2: 28622363000 | Y2: 3.9864242e+10 | Z2: 20568395000 | AA2: 0.3578568 | AB2: 281424.16
A3: 2001 | B3: D_E | C3: 1 | D3: Rev.3 | E3: 13263801000 | G3: 10613610000 | I3: 10613610000 | J3: 2650191000 | L3: 3599292000 | N3: 14928 | O3: 7 | P3: 1873944000 | Q3: 148103000 | R3: 1707000 | U3: 1928502000 | V3: 111535000 | W3: 50479997000 | X3: 50479997000 | Z3: 7014318000 | AA3: 0.33912043 | AB3: 710986.74
A4: 2001 | B4: G | C4: 1 | D4: Rev.3 | E4: 43491119000 | G4: 24957624000 | I4: 2.2794518e+10 | J4: 2.0696601e+10 | L4: 10823278000 | N4: 168971 | O4: 41141 | P4: 2205103000 | Q4: 530457000 | R4: 107333000 | U4: 1670535000 | V4: 1114492000 | W4: 14490199000 | X4: 14490199000 | Z4: 14134346000 | AA4: 0.4336662 | AB4: 147703.59
A5: 2001 | B5: H_J | C5: 1 | D5: Rev.3 | E5: 33566050000 | G5: 13456590000 | I5: 1.3454267e+10 | J5: 2.0111783e+10 | L5: 6544975000 | N5: 62695 | O5: 15659 | P5: 3337731000 | Q5: 1415592000 | R5: 1786934000 | U5: 1509319000 | V5: -154331000 | W5: 13202423000 | X5: 13202423000 | Z5: 6911615000 | AA5: 0.48637694 | AB5: 214635.78
A6: 2001 | B6: I | C6: 1 | D6: Rev.3 | E6: 6105764000 | G6: 2287136000 | I6: 2.2861472e+09 | J6: 3.8196168e+09 | L6: 1474027000 | N6: 26097 | O6: 6303 | P6: 2415023000 | Q6: 192837000 | R6: 24742000 | U6: 446253000 | V6: 39553000 | W6: 5880745000 | X6: 5880745000 | Z6: 813109000 | AA6: 0.64448594 | AB6: 87639.805
A7: 2001 | B7: L_M_N | C7: 1 | D7: Rev.3 | E7: 14837125000 | G7: 8359713000 | I7: 8.3595946e+09 | J7: 6.4775304e+09 | L7: 3864244000 | N7: 60371 | O7: 13253 | P7: 908730000 | Q7: 520775000 | R7: 158545000 | U7: 360497000 | V7: 82393000 | W7: 3280605000 | X7: 3280605000 | Z7: 4495469000 | AA7: 0.46224601 | AB7: 138472.33
A8: 2001 | B8: P | C8: 1 | D8: Rev.3 | E8: 3554736000 | G8: 2803083000 | I8: 2803083000 | J8: 751653000 | L8: 2188777000 | N8: 30186 | O8: 1863 | P8: 241141000 | Q8: 31142000 | R8: 5934000 | U8: 73414000 | V8: 1245000 | W8: 1895620000 | X8: 1895620000 | Z8: 614306000 | AA8: 0.7808463 | AB8: 92860.366
A9: 2001 | B9: Q | C9: 1 | D9: Rev.3 | E9: 20736564000 | G9: 11456887000 | I9: 11456887000 | J9: 9279677000 | L9: 8963981000 | N9: 61559 | O9: 2773 | P9: 1063210000 | Q9: 340762000 | R9: 15697000 | U9: 358413000 | V9: 204284000 | W9: 5999539000 | X9: 5999539000 | Z9: 2492906000 | AA9: 0.78240983 | AB9: 186112.3
A10: 2002 | B10: C | C10: 2 | D10: Rev.3 | E10: 104934883446 | G10: 39381506784 | I10: 3.2589108e+10 | J10: 7.2345776e+10 | K10: 1.0961481e+10 | L10: 9421078355 | M10: 1.4274361e+09 | N10: 76575 | O10: 2884 | U10: 3758469943 | V10: 5924169665 | X10: 3.808799e+10 | Y10: 5.0476907e+10 | Z10: 29960428429 | AA10: 0.23922595 | AB10: 514286.74
A11: 2002 | B11: D_E | C11: 2 | D11: Rev.3 | E11: 15787447980 | G11: 12439436732 | I11: 12439436732 | J11: 3348011248 | L11: 3806404173 | N11: 12215 | O11: 6 | U11: 3105564554 | V11: 89560282 | X11: 6.2423317e+10 | Z11: 8633032559 | AA11: 0.3059949 | AB11: 1018373.9
A12: 2002 | B12: G | C12: 2 | D12: Rev.3 | E12: 31693348520 | G12: 18177965195 | I12: 1.660246e+10 | J12: 1.5090888e+10 | L12: 7709632973 | N12: 76468 | O12: 4704 | U12: 1426375588 | V12: 632733549 | X12: 1.0354076e+10 | Z12: 10468332222 | AA12: 0.42411969 | AB12: 237719.9
A13: 2002 | B13: H_J | C13: 2 | D13: Rev.3 | E13: 37112316985 | G13: 15304944081 | I13: 1.5302302e+10 | J13: 2.1810015e+10 | L13: 6795894609 | N13: 37362 | O13: 1139 | U13: 1592530017 | V13: 69155721 | X13: 7.3606656e+09 | Z13: 8509049472 | AA13: 0.44403263 | AB13: 409639.31
A14: 2002 | B14: I | C14: 2 | D14: Rev.3 | E14: 6055117793 | G14: 2738851808 | I14: 2.7376677e+09 | J14: 3.3174501e+09 | L14: 1165502269 | N14: 14784 | O14: 837 | U14: 346961879 | V14: 206430881 | X14: 7.4495924e+09 | Z14: 1573349539 | AA14: 0.42554412 | AB14: 185257.83
A15: 2002 | B15: L_M_N | C15: 2 | D15: Rev.3 | E15: 10532305500 | G15: 5766938265 | I15: 5.7668566e+09 | J15: 4.7654489e+09 | L15: 3189588114 | N15: 36920 | O15: 1207 | U15: 319767425 | V15: -38267584 | X15: 2.3128315e+09 | Z15: 2577350151 | AA15: 0.55308172 | AB15: 156200.93
A16: 2002 | B16: P | C16: 2 | D16: Rev.3 | E16: 3635163473 | G16: 2764590458 | I16: 2764590458 | J16: 870573015 | L16: 2232779019 | N16: 29269 | O16: 795 | U16: 186228974 | V16: 1845445 | X16: 4.1293645e+09 | Z16: 531811439 | AA16: 0.80763464 | AB16: 94454.558
A17: 2002 | B17: Q | C17: 2 | D17: Rev.3 | E17: 18542655551 | G17: 9779564144 | I17: 9779564144 | J17: 8763091407 | L17: 8301959694 | N17: 56404 | O17: 726 | U17: 427982536 | V17: 308347891 | X17: 6.4899612e+09 | Z17: 1477604450 | AA17: 0.84890897 | AB17: 173384.23
A18: 2003 | B18: C | C18: 2 | D18: Rev.3 | E18: 139349946300 | G18: 41497361974 | I18: 3.4340027e+10 | J18: 1.0500992e+11 | K18: 1.5910594e+10 | L18: 10878789626 | M18: 1.6483015e+09 | N18: 83356 | O18: 2884 | P18: 6899547696 | Q18: 5558448986 | R18: 5256351292 | U18: 4714590576 | V18: 6090823735 | W18: 48103564060 | X18: 48103564060 | Y18: 6.5662459e+10 | Z18: 30618572348 | AA18: 0.26215617 | AB18: 497832.93
A19: 2003 | B19: D_E | C19: 2 | D19: Rev.3 | E19: 17778374536 | G19: 15099711405 | I19: 15099711405 | J19: 2678663131 | L19: 3709025707 | N19: 11033 | O19: 6 | P19: 1881480432 | Q19: 729819150 | R19: 289523 | U19: 2816673366 | V19: 71005452 | W19: 18404738826 | X19: 18404738826 | Z19: 11390685698 | AA19: 0.24563554 | AB19: 1368595.3
A20: 2003 | B20: G | C20: 2 | D20: Rev.3 | E20: 37563631203 | G20: 21571353022 | I20: 1.9701739e+10 | J20: 1.7861892e+10 | L20: 7998489144 | N20: 77964 | O20: 4704 | P20: 1137150229 | Q20: 345789196 | R20: 84676957 | U20: 1828622094 | V20: 718525744 | W20: 13454000561 | X20: 13454000561 | Z20: 13572863878 | AA20: 0.37079219 | AB20: 276683.51
A21: 2003 | B21: H_J | C21: 2 | D21: Rev.3 | E21: 45516690384 | G21: 16906173266 | I21: 1.6903255e+10 | J21: 2.8613436e+10 | L21: 6746978974 | N21: 36295 | O21: 1139 | P21: 2989215591 | Q21: 1954096578 | R21: 336383626 | U21: 4184128201 | V21: 148694272 | W21: 16977971617 | X21: 16977971617 | Z21: 10159194292 | AA21: 0.39908375 | AB21: 465798.96
A22: 2003 | B22: I | C22: 2 | D22: Rev.3 | E22: 7545694909 | G22: 3215599713 | I22: 3.2142095e+09 | J22: 4.3314854e+09 | L22: 1331138827 | N22: 15423 | O22: 837 | P22: 407835768 | Q22: 234293111 | R22: 4134443 | U22: 581911564 | V22: 185578578 | W22: 15394752061 | X22: 15394752061 | Z22: 1884460886 | AA22: 0.41396285 | AB22: 208493.79
A23: 2003 | B23: L_M_N | C23: 2 | D23: Rev.3 | E23: 10840882783 | G23: 5781255267 | I23: 5.7811734e+09 | J23: 5.0597094e+09 | L23: 3250196651 | N23: 36576 | O23: 1207 | P23: 893749498 | Q23: 392670668 | R23: 60040937 | U23: 446760432 | V23: -81377996 | W23: 3036697582 | X23: 3036697582 | Z23: 2531058616 | AA23: 0.56219567 | AB23: 158061.44
A24: 2003 | B24: P | C24: 2 | D24: Rev.3 | E24: 4020897277 | G24: 3041969189 | I24: 3041969189 | J24: 978928088 | L24: 2333305509 | N24: 30136 | O24: 795 | P24: 265611515 | Q24: 182986853 | R24: 6872122 | U24: 202734943 | V24: 1700570 | W24: 4535928555 | X24: 4535928555 | Z24: 708663680 | AA24: 0.76703785 | AB24: 100941.37
A25: 2003 | B25: Q | C25: 2 | D25: Rev.3 | E25: 20144437327 | G25: 10367277432 | I25: 10367277432 | J25: 9777159895 | L25: 8237357729 | N25: 54436 | O25: 726 | P25: 464436226 | Q25: 160670968 | R25: 16922814 | U25: 612598654 | V25: 532348671 | W25: 8950823549 | X25: 8950823549 | Z25: 2129919703 | AA25: 0.79455361 | AB25: 190448.92
A26: 2004 | B26: C | C26: 2 | D26: Rev.3 | E26: 179010449525 | G26: 52621053735 | I26: 4.3545139e+10 | J26: 1.3546531e+11 | K26: 2.0525047e+10 | L26: 12139435357 | M26: 1.8393084e+09 | N26: 88653 | O26: 3252 | P26: 6396127195 | Q26: 3154522472 | R26: 1599697016 | S26: 1743085329 | T26: 3342782345 | U26: 5136920717 | V26: 7039185004 | W26: 50525577181 | X26: 50525577181 | Y26: 7.2889933e+10 | Z26: 40481618378 | AA26: 0.23069541 | AB26: 593562.02
A27: 2004 | B27: D_E | C27: 2 | D27: Rev.3 | E27: 18970896638 | G27: 16452542193 | I27: 16452542193 | J27: 2518354445 | L27: 4318586343 | N27: 11278 | O27: 8 | P27: 1586645703 | Q27: 1391609954 | R27: 577445 | S27: 0 | T27: 577445 | U27: 3527584731 | V27: 193662937 | W27: 69005735625 | X27: 69005735625 | Z27: 12133955850 | AA27: 0.26248748 | AB27: 1458817.4
A28: 2004 | B28: G | C28: 2 | D28: Rev.3 | E28: 44736252618 | G28: 25542912801 | I28: 2.332908e+10 | J28: 2.1407173e+10 | L28: 8750816236 | N28: 80808 | O28: 5540 | P28: 2848082374 | Q28: 693786571 | R28: 168379555 | S28: 743240013 | T28: 911619568 | U28: 2071656593 | V28: 891739416 | W28: 14305115357 | X28: 14305115357 | Z28: 16792096565 | AA28: 0.34259273 | AB28: 316093.86
A29: 2004 | B29: H_J | C29: 2 | D29: Rev.3 | E29: 54138973445 | G29: 18769614747 | I29: 1.8766374e+10 | J29: 3.5372599e+10 | L29: 7257265654 | N29: 38895 | O29: 1403 | P29: 6988113014 | Q29: 4667216558 | R29: 443287668 | S29: 940736307 | T29: 1384023975 | U29: 4707582011 | V29: 180141199 | W29: 23318179581 | X29: 23318179581 | Z29: 11512349093 | AA29: 0.38664969 | AB29: 482571.4
A30: 2004 | B30: I | C30: 2 | D30: Rev.3 | E30: 7527262326 | G30: 3225745138 | I30: 3.2243505e+09 | J30: 4.3029118e+09 | L30: 1362647439 | N30: 14104 | O30: 810 | P30: 564815404 | Q30: 101735015 | R30: 0 | S30: 17194896 | T30: 17194896 | U30: 618478957 | V30: 151819588 | W30: 12857715294 | X30: 12857715294 | Z30: 1863097699 | AA30: 0.42242874 | AB30: 228711.37
A31: 2004 | B31: L_M_N | C31: 2 | D31: Rev.3 | E31: 12469844085 | G31: 6554832803 | I31: 6.5547399e+09 | J31: 5.9151042e+09 | L31: 3515024005 | N31: 33674 | O31: 1340 | P31: 1110214370 | Q31: 616807060 | R31: 128520209 | S31: 183666728 | T31: 312186937 | U31: 454902760 | V31: -111867613 | W31: 3709336385 | X31: 3709336385 | Z31: 3039808798 | AA31: 0.53624922 | AB31: 194655.6
A32: 2004 | B32: P | C32: 2 | D32: Rev.3 | E32: 4122763764 | G32: 3114011412 | I32: 3114011412 | J32: 1008752352 | L32: 2364813124 | N32: 28379 | O32: 850 | P32: 442468386 | Q32: 85104732 | R32: 12004244 | S32: 14446685 | T32: 26450929 | U32: 183943843 | V32: 1516610 | W32: 4097580261 | X32: 4097580261 | Z32: 749198288 | AA32: 0.75941055 | AB32: 109729.43
A33: 2004 | B33: Q | C33: 2 | D33: Rev.3 | E33: 21510528473 | G33: 10967962939 | I33: 10967962939 | J33: 10542565534 | L33: 8298900124 | N33: 52548 | O33: 790 | P33: 1020214687 | Q33: 370879850 | R33: 20163040 | S33: 147177599 | T33: 167340639 | U33: 640676128 | V33: 524173728 | W33: 9519982217 | X33: 9519982217 | Z33: 2669062815 | AA33: 0.75664918 | AB33: 208722.75
A34: 2005 | B34: C | C34: 2 | D34: Rev.3 | E34: 184862461743 | G34: 53991760706 | I34: 4.4679431e+10 | J34: 1.4018303e+11 | K34: 2.1239853e+10 | L34: 14615233399 | M34: 2.2144293e+09 | N34: 102414 | O34: 3445 | P34: 6464007473 | Q34: 2747259075 | R34: 2116008436 | S34: 2111494326 | T34: 4227502762 | U34: 5058292667 | V34: 7651885206 | W34: 52418214093 | X34: 52418214093 | Y34: 7.5872497e+10 | Z34: 39376527307 | AA34: 0.27069377 | AB34: 527191.21
A35: 2005 | B35: D_E | C35: 2 | D35: Rev.3 | E35: 21452171857 | G35: 17681330593 | I35: 17681330593 | J35: 3770841264 | L35: 3774749843 | N35: 10749 | O35: 9 | P35: 6130481812 | Q35: 157381971 | R35: 0 | S35: 10139634 | T35: 10139634 | U35: 3491133822 | V35: 258939881 | W35: 119415827794 | X35: 119415827794 | Z35: 13906580750 | AA35: 0.21348788 | AB35: 1644928
A36: 2005 | B36: G | C36: 2 | D36: Rev.3 | E36: 52055365572 | G36: 30604340361 | I36: 2.7951827e+10 | J36: 2.4103538e+10 | L36: 10891239572 | N36: 88696 | O36: 5425 | P36: 2485425948 | Q36: 476330674 | R36: 146988046 | S36: 501187302 | T36: 648175348 | U36: 1882974266 | V36: 1327172831 | W36: 14149463192 | X36: 14149463192 | Z36: 19713100789 | AA36: 0.35587238 | AB36: 345047.58
A37: 2005 | B37: H_J | C37: 2 | D37: Rev.3 | E37: 58995279052 | G37: 22019098542 | I37: 2.2015297e+10 | J37: 3.6979982e+10 | L37: 8354766526 | N37: 42234 | O37: 1451 | P37: 4434586962 | Q37: 1623564422 | R37: 1255663280 | S37: 822643912 | T37: 2078307192 | U37: 4755443419 | V37: 10796371 | W37: 23087450461 | X37: 23087450461 | Z37: 13664332016 | AA37: 0.37943272 | AB37: 521359.53
A38: 2005 | B38: I | C38: 2 | D38: Rev.3 | E38: 8281031530 | G38: 3767948397 | I38: 3.7663194e+09 | J38: 4.5147122e+09 | L38: 1616158132 | N38: 15568 | O38: 834 | P38: 238518748 | Q38: 157340735 | R38: 63255653 | S38: 52892693 | T38: 116148346 | U38: 681078239 | V38: 145165012 | W38: 11692776848 | X38: 11692776848 | Z38: 2151790265 | AA38: 0.42892258 | AB38: 242031.63
A39: 2005 | B39: L_M_N | C39: 2 | D39: Rev.3 | E39: 15934155356 | G39: 8374925674 | I39: 8.374807e+09 | J39: 7.5593483e+09 | L39: 5069118049 | N39: 41494 | O39: 1455 | P39: 1182629165 | Q39: 675555411 | R39: 168007029 | S39: 294530786 | T39: 462537815 | U39: 597692961 | V39: -97991671 | W39: 4032805057 | X39: 4032805057 | Z39: 3305807625 | AA39: 0.6052732 | AB39: 201834.62
A40: 2005 | B40: P | C40: 2 | D40: Rev.3 | E40: 4730612582 | G40: 3549115924 | I40: 3549115924 | J40: 1181496658 | L40: 2735589275 | N40: 32524 | O40: 873 | P40: 308786468 | Q40: 106489219 | R40: 14147369 | S40: 22900523 | T40: 37047892 | U40: 169154791 | V40: 3417836 | W40: 3699553497 | X40: 3699553497 | Z40: 813526649 | AA40: 0.77078048 | AB40: 109122.98
...

Sheet rama-C
A1: anno | B1: seccion | C1: epoca | D1: ciiu_version | E1: vbp_pp | F1: vbp_pb | G1: vab_pp | H1: vab_pb | I1: vab_pb_estimado | J1: consumo_intermedio_estimado | K1: capital_circulante_constante_adelantado | L1: remuneraciones | M1: capital_variable_adelantado | N1: puestos_trabajo | O1: n_empresas | P1: fbcf | Q1: fbkf_maq_eq | R1: adquisiciones_importadas | S1: adquisiciones_origen_importado | T1: importaciones_maquinaria | U1: consumo_capital_fijo | V1: impuestos_netos | W1: stock_capital | X1: stock_capital_imputado | Y1: capital_total_adelantado | Z1: excedente_bruto | AA1: part_salarial | AB1: productividad | AC1: Ganancia desp de impuestos
A2: 2001 | B2: C | C2: 1 | D2: Rev.3 | E2: 89240215000 | G2: 32030854000 | I2: 2.6506273e+10 | J2: 6.2733942e+10 | K2: 9.5051428e+09 | L2: 11462459000 | M2: 1.7367362e+09 | N2: 113817 | O2: 12367 | P2: 3539644000 | Q2: 2057120000 | R2: 1075519000 | U2: 3127411000 | V2: 6829485000 | W2: 28622363000 | X2: 28622363000 | Y2: 3.9864242e+10 | Z2: 20568395000 | AA2: 0.3578568 | AB2: 281424.16 | AC2: =I2-L2-U2-V2 -> 5.0869177e+09 | AD2: =AC2/Y2 -> 0.12760603
A3: 2002 | B3: C | C3: 2 | D3: Rev.3 | E3: 104934883446 | G3: 39381506784 | I3: 3.2589108e+10 | J3: 7.2345776e+10 | K3: 1.0961481e+10 | L3: 9421078355 | M3: 1.4274361e+09 | N3: 76575 | O3: 2884 | U3: 3758469943 | V3: 5924169665 | X3: 3.808799e+10 | Y3: 5.0476907e+10 | Z3: 29960428429 | AA3: 0.23922595 | AB3: 514286.74 | AC3: =I3-L3-U3-V3 -> 1.348539e+10 | AD3: =AC3/Y3 -> 0.26715959
A4: 2003 | B4: C | C4: 2 | D4: Rev.3 | E4: 139349946300 | G4: 41497361974 | I4: 3.4340027e+10 | J4: 1.0500992e+11 | K4: 1.5910594e+10 | L4: 10878789626 | M4: 1.6483015e+09 | N4: 83356 | O4: 2884 | P4: 6899547696 | Q4: 5558448986 | R4: 5256351292 | U4: 4714590576 | V4: 6090823735 | W4: 48103564060 | X4: 48103564060 | Y4: 6.5662459e+10 | Z4: 30618572348 | AA4: 0.26215617 | AB4: 497832.93 | AC4: =I4-L4-U4-V4 -> 1.2655823e+10 | AD4: =AC4/Y4 -> 0.19274062
A5: 2004 | B5: C | C5: 2 | D5: Rev.3 | E5: 179010449525 | G5: 52621053735 | I5: 4.3545139e+10 | J5: 1.3546531e+11 | K5: 2.0525047e+10 | L5: 12139435357 | M5: 1.8393084e+09 | N5: 88653 | O5: 3252 | P5: 6396127195 | Q5: 3154522472 | R5: 1599697016 | S5: 1743085329 | T5: 3342782345 | U5: 5136920717 | V5: 7039185004 | W5: 50525577181 | X5: 50525577181 | Y5: 7.2889933e+10 | Z5: 40481618378 | AA5: 0.23069541 | AB5: 593562.02 | AC5: =I5-L5-U5-V5 -> 1.9229598e+10 | AD5: =AC5/Y5 -> 0.26381693
A6: 2005 | B6: C | C6: 2 | D6: Rev.3 | E6: 184862461743 | G6: 53991760706 | I6: 4.4679431e+10 | J6: 1.4018303e+11 | K6: 2.1239853e+10 | L6: 14615233399 | M6: 2.2144293e+09 | N6: 102414 | O6: 3445 | P6: 6464007473 | Q6: 2747259075 | R6: 2116008436 | S6: 2111494326 | T6: 4227502762 | U6: 5058292667 | V6: 7651885206 | W6: 52418214093 | X6: 52418214093 | Y6: 7.5872497e+10 | Z6: 39376527307 | AA6: 0.27069377 | AB6: 527191.21 | AC6: =I6-L6-U6-V6 -> 1.735402e+10 | AD6: =AC6/Y6 -> 0.22872609
A7: 2006 | B7: C | C7: 3 | D7: Rev.3 | E7: 1.850396e+11 | G7: 5.4017528e+10 | I7: 4.4700754e+10 | J7: 1.4033884e+11 | K7: 2.1263461e+10 | L7: 1.3982311e+10 | M7: 2.118532e+09 | N7: 63928.853 | P7: 6.5161369e+09 | Q7: 4.2278276e+09 | R7: 2.1827562e+09 | S7: 1.4258711e+09 | T7: 3.6086273e+09 | U7: 4.2569136e+09 | V7: 8.4664645e+09 | W7: 5.7185677e+10 | X7: 5.7185677e+10 | Y7: 8.056767e+10 | Z7: 4.0035217e+10 | AA7: 0.25884767 | AB7: 844963.2 | AC7: =I7-L7-U7-V7 -> 1.7995065e+10 | AD7: =AC7/Y7 -> 0.22335342
A8: 2007 | B8: C | C8: 3 | D8: Rev.3 | E8: 2.35394e+11 | G8: 7.0661648e+10 | I8: 5.8474148e+10 | J8: 1.7691985e+11 | K8: 2.6806038e+10 | L8: 1.9975832e+10 | M8: 3.0266412e+09 | N8: 100576.01 | P8: 1.735929e+10 | Q8: 5.9547781e+09 | R8: 2.0501427e+09 | S8: 2.5603315e+09 | T8: 4.6104742e+09 | U8: 5.9348309e+09 | V8: 8.4529852e+09 | W8: 8.8288213e+10 | X8: 8.8288213e+10 | Y8: 1.1812089e+11 | Z8: 5.0685816e+10 | AA8: 0.28269695 | AB8: 702569.59 | AC8: =I8-L8-U8-V8 -> 2.41105e+10 | AD8: =AC8/Y8 -> 0.20411715
A9: 2008 | B9: C | C9: 4 | D9: Rev.4 | E9: 2.8499569e+11 | G9: 8.0292211e+10 | I9: 6.6443662e+10 | J9: 2.1855203e+11 | K9: 3.3113944e+10 | L9: 2.4291156e+10 | M9: 3.6804782e+09 | N9: 103902.69 | P9: 1.7442926e+10 | Q9: 1.0194336e+10 | R9: 3.6551334e+09 | S9: 3.7460905e+09 | T9: 7.4012239e+09 | U9: 8.098413e+09 | V9: 7.35581e+09 | W9: 1.0797121e+11 | X9: 1.0797121e+11 | Y9: 1.4476563e+11 | Z9: 5.6001055e+10 | AA9: 0.3025344 | AB9: 772763.58 | AC9: =I9-L9-U9-V9 -> 2.6698283e+10 | AD9: =AC9/Y9 -> 0.18442418
A10: 2009 | B10: C | C10: 4 | D10: Rev.4 | E10: 2.6234716e+11 | G10: 7.8234884e+10 | I10: 6.4741176e+10 | J10: 1.9760598e+11 | K10: 2.9940301e+10 | L10: 2.9743371e+10 | M10: 4.5065713e+09 | N10: 104036.65 | P10: 7.9610854e+09 | Q10: 5.8014096e+09 | R10: 2.4158472e+09 | S10: 1.4778565e+09 | T10: 3.8937037e+09 | U10: 7.8032167e+09 | V10: 9.1759088e+09 | W10: 9.3192118e+10 | X10: 9.3192118e+10 | Y10: 1.2763899e+11 | Z10: 4.8491513e+10 | AA10: 0.38018041 | AB10: 751993.51 | AC10: =I10-L10-U10-V10 -> 1.801868e+10 | AD10: =AC10/Y10 -> 0.14116909
A11: 2010 | B11: C | C11: 4 | D11: Rev.4 | E11: 2.9861469e+11 | G11: 9.5564091e+10 | I11: 7.9081496e+10 | J11: 2.1953319e+11 | K11: 3.3262604e+10 | L11: 3.413185e+10 | M11: 5.1714925e+09 | N11: 112274.19 | P11: 1.0581329e+10 | Q11: 6.5272666e+09 | R11: 2.6329602e+09 | S11: 1.8229898e+09 | T11: 4.45595e+09 | U11: 8.1548456e+09 | V11: 1.2317166e+10 | W11: 9.973781e+10 | X11: 9.973781e+10 | Y11: 1.3817191e+11 | Z11: 6.1432241e+10 | AA11: 0.35716188 | AB11: 851167.02 | AC11: =I11-L11-U11-V11 -> 2.4477634e+10 | AD11: =AC11/Y11 -> 0.17715348
A12: 2011 | B12: C | C12: 4 | D12: Rev.4 | E12: 3.2272011e+11 | G12: 9.770659e+10 | I12: 8.0854464e+10 | J12: 2.4186565e+11 | K12: 3.664631e+10 | L12: 3.8240757e+10 | M12: 5.7940541e+09 | N12: 109399.62 | O12: 2202 | U12: 8.1848116e+09 | V12: 1.8825379e+10 | X12: 1.2215015e+11 | Y12: 1.6459051e+11 | Z12: 5.9465833e+10 | AA12: 0.3913836 | AB12: 893116.33 | AC12: =I12-L12-U12-V12 -> 1.5603516e+10 | AD12: =AC12/Y12 -> 0.094802037
A13: 2012 | B13: C | C13: 4 | D13: Rev.4 | E13: 3.6649548e+11 | G13: 9.9292175e+10 | I13: 8.2166571e+10 | J13: 2.8432891e+11 | K13: 4.3080137e+10 | L13: 4.3787875e+10 | M13: 6.6345265e+09 | N13: 110138.75 | P13: 1.7144628e+10 | Q13: 1.186762e+10 | R13: 5.9741866e+09 | S13: 3.1526135e+09 | T13: 9.1268001e+09 | U13: 9.2006411e+09 | V13: 1.6525007e+10 | W13: 1.1807022e+11 | X13: 1.1807022e+11 | Y13: 1.6778489e+11 | Z13: 5.55043e+10 | AA13: 0.44100026 | AB13: 901518.99 | AC13: =I13-L13-U13-V13 -> 1.2653049e+10 | AD13: =AC13/Y13 -> 0.075412326
A14: 2013 | B14: C | C14: 4 | D14: Rev.4 | E14: 3.9349558e+11 | G14: 1.1189604e+11 | I14: 9.2596558e+10 | J14: 3.0089902e+11 | K14: 4.5590761e+10 | L14: 5.0186679e+10 | M14: 7.6040423e+09 | N14: 109797.75 | P14: 2.8790673e+10 | Q14: 1.8295653e+10 | R14: 2.4797926e+09 | S14: 1.6298812e+10 | T14: 1.8778604e+10 | U14: 9.6344566e+09 | V14: 2.0496674e+10 | W14: 1.3030327e+11 | X14: 1.3030327e+11 | Y14: 1.8349807e+11 | Z14: 6.1709356e+10 | AA14: 0.44851168 | AB14: 1019110.5 | AC14: =I14-L14-U14-V14 -> 1.2278747e+10 | AD14: =AC14/Y14 -> 0.066914858
A15: 2014 | B15: C | C15: 4 | D15: Rev.4 | E15: 4.5364092e+11 | G15: 1.3078013e+11 | I15: 1.0822358e+11 | J15: 3.4541733e+11 | K15: 5.233596e+10 | L15: 5.6837646e+10 | M15: 8.6117646e+09 | N15: 107700.43 | P15: 7.8176629e+10 | Q15: 5.2611955e+10 | R15: 2.2171191e+09 | S15: 4.8143911e+10 | T15: 5.036103e+10 | U15: 1.2235322e+10 | V15: 2.2082789e+10 | W15: 1.9842942e+11 | X15: 1.9842942e+11 | Y15: 2.5937714e+11 | Z15: 7.3942486e+10 | AA15: 0.4346046 | AB15: 1214295.4 | AC15: =I15-L15-U15-V15 -> 1.7067828e+10 | AD15: =AC15/Y15 -> 0.06580313
A16: 2015 | B16: C | C16: 4 | D16: Rev.4 | E16: 4.7809497e+11 | G16: 1.5193967e+11 | I16: 1.257336e+11 | J16: 3.5236137e+11 | K16: 5.3388087e+10 | L16: 6.1103873e+10 | M16: 9.2581625e+09 | N16: 103791.21 | P16: 2.6806672e+10 | Q16: 1.6410901e+10 | R16: 1.3932607e+09 | S16: 6.2827403e+09 | T16: 7.676001e+09 | U16: 1.4988601e+10 | V16: 2.4800676e+10 | W16: 2.0781379e+11 | X16: 2.0781379e+11 | Y16: 2.7046004e+11 | Z16: 9.0835801e+10 | AA16: 0.40215877 | AB16: 1463897.3 | AC16: =I16-L16-U16-V16 -> 2.4840445e+10 | AD16: =AC16/Y16 -> 0.091845157
A17: 2016 | B17: C | C17: 4 | D17: Rev.4 | E17: 4.8828286e+11 | G17: 1.5538284e+11 | I17: 1.2858289e+11 | J17: 3.5969996e+11 | K17: 5.4499994e+10 | L17: 6.5854042e+10 | M17: 9.9778851e+09 | N17: 100240.45 | P17: 1.7409372e+10 | Q17: 7.9574019e+09 | R17: 1.6947138e+09 | S17: 4.3099059e+09 | T17: 6.0046197e+09 | U17: 1.6145912e+10 | V17: 2.6902001e+10 | W17: 2.188245e+11 | X17: 2.188245e+11 | Y17: 2.8330238e+11 | Z17: 8.9528797e+10 | AA17: 0.42381799 | AB17: 1550101.2 | AC17: =I17-L17-U17-V17 -> 1.9680939e+10 | AD17: =AC17/Y17 -> 0.069469729
A18: 2017 | B18: C | C18: 5 | D18: Rev.4 | E18: 4.8414153e+11 | F18: 4.5578209e+11 | G18: 1.6442457e+11 | H18: 1.3606514e+11 | I18: 1.3606514e+11 | J18: 3.4807639e+11 | K18: 5.2738847e+10 | L18: 7.0584977e+10 | M18: 1.0694694e+10 | N18: 97466.997 | P18: 1.703624e+10 | Q18: 8.4810375e+09 | R18: 1.7263034e+09 | S18: 2.8971526e+09 | T18: 4.623456e+09 | U18: 1.5918677e+10 | V18: 1.9633084e+09 | W18: 2.097731e+11 | X18: 2.097731e+11 | Y18: 2.7320664e+11 | Z18: 9.3839595e+10 | AA18: 0.42928485 | AB18: 1686976.9 | AC18: =I18-L18-U18-V18 -> 4.7598175e+10 | AD18: =AC18/Y18 -> 0.17422042
A19: 2018 | B19: C | C19: 5 | D19: Rev.4 | E19: 5.7003685e+11 | F19: 5.3964224e+11 | G19: 1.9788533e+11 | H19: 1.6749072e+11 | I19: 1.6749072e+11 | J19: 4.0254613e+11 | K19: 6.0991837e+10 | L19: 7.6120685e+10 | M19: 1.1533437e+10 | N19: 94566.086 | P19: 2.1403884e+10 | Q19: 9.3987612e+09 | R19: 2.3443011e+09 | S19: 3.8755945e+09 | T19: 6.2198956e+09 | U19: 1.6454136e+10 | V19: 1.2152229e+09 | W19: 2.3094465e+11 | X19: 2.3094465e+11 | Y19: 303469927276 | Z19: 1.2176465e+11 | AA19: 0.38467068 | AB19: 2092561.3 | AC19: =I19-L19-U19-V19 -> 7.3700681e+10 | AD19: =AC19/Y19 -> 0.24285992
A20: 2019 | B20: C | C20: 5 | D20: Rev.4 | E20: 601651424497 | F20: 569209962569 | G20: 190772526038 | H20: 158331064110 | I20: 158331064110 | J20: 443320360387 | K20: 6.7169752e+10 | L20: 80999471228 | M20: 1.2272647e+10 | N20: 90481 | P20: 30759048024 | Q20: 10582877554 | R20: 10715087960 | S20: 3917218825 | T20: 14632306785 | U20: 1.8470371e+10 | V20: 1.7013764e+09 | W20: 259048160897 | X20: 259048160897 | Y20: 3.3849056e+11 | Z20: 109773054810 | AA20: 0.42458667 | AB20: 2108426.4 | AC20: =I20-L20-U20-V20 -> 5.7159846e+10 | AD20: =AC20/Y20 -> 0.16886688
A21: 2020 | B21: C | C21: 5 | D21: Rev.4 | E21: 6.0081753e+11 | F21: 5.6925511e+11 | G21: 1.8296311e+11 | H21: 1.5140069e+11 | I21: 1.5140069e+11 | J21: 4.4941684e+11 | K21: 6.809346e+10 | L21: 7.8278216e+10 | M21: 1.1860336e+10 | N21: 84764.465 | O21: 1759 | P21: 4.094156e+10 | Q21: 9.808505e+09 | R21: 3.2754489e+09 | S21: 2.7093516e+09 | T21: 5.9848005e+09 | U21: 1.9749526e+10 | V21: -1.8273468e+09 | W21: 2.963226e+11 | X21: 2.963226e+11 | Y21: 3.762764e+11 | Z21: 1.0468489e+11 | AA21: 0.42783606 | AB21: 2158488.4 | AC21: =I21-L21-U21-V21 -> 5.5200295e+10 | AD21: =AC21/Y21 -> 0.14670146
A22: 2021 | B22: C | C22: 5 | D22: Rev.4 | E22: 7.404514e+11 | F22: 7.2951903e+11 | G22: 2.2497468e+11 | H22: 2.1404231e+11 | I22: 2.1404231e+11 | J22: 5.2640909e+11 | K22: 7.9758953e+10 | L22: 8.4122099e+10 | M22: 1.2745773e+10 | N22: 86333.094 | P22: 8.3942984e+10 | Q22: 1.8626904e+10 | R22: 3.3123653e+09 | S22: 6.0037884e+09 | T22: 9.3161537e+09 | U22: 2.1739334e+10 | V22: -1.1586107e+09 | W22: 3.7719399e+11 | X22: 3.7719399e+11 | Y22: 4.6969871e+11 | Z22: 1.4085258e+11 | AA22: 0.37391807 | AB22: 2605891.5 | AC22: =I22-L22-U22-V22 -> 1.0933949e+11 | AD22: =AC22/Y22 -> 0.23278643
A23: 2022 | B23: C | C23: 5 | D23: Rev.4 | E23: 8.8744811e+11 | F23: 8.472213e+11 | G23: 2.6553605e+11 | H23: 2.2530924e+11 | I23: 2.2530924e+11 | J23: 6.6213887e+11 | K23: 1.0032407e+11 | L23: 9.5609914e+10 | M23: 1.4486351e+10 | N23: 89467.506 | P23: 6.9687014e+10 | Q23: 1.724295e+10 | R23: 4.1405769e+09 | S23: 5.18038e+09 | T23: 9.320957e+09 | U23: 2.1523442e+10 | V23: -2.7008478e+09 | W23: 3.9260348e+11 | X23: 3.9260348e+11 | Y23: 5.074139e+11 | Z23: 1.6992614e+11 | AA23: 0.36006378 | AB23: 2967960.8 | AC23: =I23-L23-U23-V23 -> 1.1087673e+11 | AD23: =AC23/Y23 -> 0.21851339
A24: 2023 | B24: C | C24: 5 | D24: Rev.4 | E24: 8.095925e+11 | F24: 7.6790402e+11 | G24: 2.4012716e+11 | H24: 1.9843867e+11 | I24: 1.9843867e+11 | J24: 6.1115383e+11 | K24: 9.2599065e+10 | L24: 1.046198e+11 | M24: 1.5851485e+10 | N24: 89501.941 | P24: 5.6457789e+10 | Q24: 3.8688156e+10 | R24: 3.0484519e+09 | S24: 4.9906452e+09 | T24: 8.0390971e+09 | U24: 2.4684324e+10 | V24: -1.909039e+09 | W24: 4.0246279e+11 | X24: 4.0246279e+11 | Y24: 5.1091334e+11 | Z24: 1.3550736e+11 | AA24: 0.43568499 | AB24: 2682926.8 | AC24: =I24-L24-U24-V24 -> 7.1043588e+10 | AD24: =AC24/Y24 -> 0.13905213
A25: 2024 | B25: C | C25: 5 | D25: Rev.4 | E25: 8.5807161e+11 | F25: 8.12702e+11 | G25: 2.6397033e+11 | H25: 2.1860072e+11 | I25: 2.1860072e+11 | J25: 6.3947089e+11 | K25: 9.6889529e+10 | L25: 1.1292427e+11 | M25: 1.7109737e+10 | N25: 90863.927 | P25: 4.3801058e+10 | Q25: 2.2430814e+10 | R25: 2.2133014e+09 | S25: 6.1907634e+09 | T25: 8.4040648e+09 | U25: 2.7515759e+10 | V25: -2.0029493e+09 | W25: 4.3696596e+11 | X25: 4.3696596e+11 | Y25: 5.5096522e+11 | Z25: 1.5104606e+11 | AA25: 0.42779152 | AB25: 2905116.8 | AC25: =I25-L25-U25-V25 -> 8.0163643e+10 | AD25: =AC25/Y25 -> 0.14549674

Sheet check-calidad-C
A1: anno | B1: vab_vbp | C1: consumo_intermedio_estimado | D1: remuneraciones_vab | E1: stock_vab
A2: 2001 | B2: 0.35892847 | C2: 6.2733942e+10 | D2: 0.3578568 | E2: 0.89358726
A3: 2002 | B3: 0.37529471 | C3: 7.2345776e+10 | D3: 0.23922595 | E3: 0.96715421
A4: 2003 | B4: 0.29779245 | C4: 1.0500992e+11 | D4: 0.26215617 | E4: 1.1591957
A5: 2004 | B5: 0.29395521 | C5: 1.3546531e+11 | D5: 0.23069541 | E5: 0.96017798
A6: 2005 | B6: 0.29206449 | C6: 1.4018303e+11 | D6: 0.27069377 | E6: 0.9708558
A7: 2006 | B7: 0.29192415 | C7: 1.4033884e+11 | D7: 0.25884767 | E7: 1.0586504
A8: 2007 | B8: 0.30018457 | C8: 1.7691985e+11 | D8: 0.28269695 | E8: 1.2494502
A9: 2008 | B9: 0.28173131 | C9: 2.1855203e+11 | D9: 0.3025344 | E9: 1.3447283
A10: 2009 | B10: 0.29821129 | C10: 1.9760598e+11 | D10: 0.38018041 | E10: 1.1911837
A11: 2010 | B11: 0.32002475 | C11: 2.1953319e+11 | D11: 0.35716188 | E11: 1.0436746
A12: 2011 | B12: 0.30275953 | C12: 2.4186565e+11 | D12: 0.3913836 | E12: 1.2501731
A13: 2012 | B13: 0.27092333 | C13: 2.8432891e+11 | D13: 0.44100026 | E13: 1.1891191
... A25: 2024 | B25: 0.30763205 | C25: 6.3947089e+11 | D25: 0.42779152 | E25: 1.6553602

Sheet economia_total
A1: anno | B1: seccion | C1: epoca | D1: ciiu_version | E1: vbp_pp | F1: vbp_pb | G1: vab_pp | H1: vab_pb | I1: vab_pb_estimado | J1: consumo_intermedio_estimado | K1: capital_circulante_constante_adelantado | L1: remuneraciones | M1: capital_variable_adelantado | N1: puestos_trabajo | O1: n_empresas | P1: fbcf | Q1: fbkf_maq_eq | R1: adquisiciones_importadas | S1: adquisiciones_origen_importado | T1: importaciones_maquinaria | U1: consumo_capital_fijo | V1: impuestos_netos | W1: stock_capital | X1: stock_capital_imputado | Y1: capital_total_adelantado | Z1: excedente_bruto | AA1: part_salarial | AB1: productividad
A2: 2001 | B2: economia_total | C2: 1 | D2: Rev.3 | E2: 224795374000 | G2: 105965497000 | I2: 9.827438e+10 | J2: 1.2652099e+11 | K2: 3.0124046e+10 | L2: 48921033000 | M2: 11647865000 | N2: 538624 | O2: 93366 | P2: 15584526000 | Q2: 5236788000 | R2: 3176411000 | U2: 9474344000 | V2: 8228656000 | W2: 123851491000 | X2: 123851491000 | Y2: 1.656234e+11 | Z2: 57044464000 | AA2: 0.46166945 | AB2: 196733.71
A3: 2002 | B3: economia_total | C3: 2 | D3: Rev.3 | E3: 228293239248 | G3: 106353797467 | I3: 9.7981986e+10 | J3: 1.3031125e+11 | K3: 3.1026489e+10 | L3: 42622839206 | M3: 1.0148295e+10 | N3: 339997 | O3: 12298 | U3: 11163880916 | V3: 7193975850 | X3: 1.2279995e+11 | Y3: 1.6397473e+11 | Z3: 63730958261 | AA3: 0.40076462 | AB3: 312808.05
A4: 2003 | B4: economia_total | C4: 2 | D4: Rev.3 | E4: 282760554719 | G4: 117480701268 | I4: 1.0844936e+11 | J4: 1.7431119e+11 | K4: 4.1502665e+10 | L4: 44485282167 | M4: 1.0591734e+10 | N4: 345219 | O4: 12298 | P4: 14939026955 | Q4: 9558775510 | R4: 5765671714 | U4: 15388019830 | V4: 7667299026 | W4: 128858476811 | X4: 128858476811 | Y4: 1.8095288e+11 | Z4: 72995419101 | AA4: 0.37866034 | AB4: 340307.75
A5: 2004 | B5: economia_total | C5: 2 | D5: Rev.3 | E5: 342486970874 | G5: 137248675768 | I5: 1.259542e+11 | J5: 2.1653277e+11 | K5: 5.1555422e+10 | L5: 48007488282 | M5: 1.1430354e+10 | N5: 348339 | O5: 13993 | P5: 20956681133 | Q5: 11081662212 | R5: 2372629177 | S5: 3789547557 | T5: 6162176734 | U5: 17341745740 | V5: 8870370869 | W5: 187339221901 | X5: 187339221901 | Y5: 2.50325e+11 | Z5: 89241187486 | AA5: 0.34978471 | AB5: 394008.93
A6: 2005 | B6: economia_total | C6: 2 | D6: Rev.3 | E6: 370267989847 | G6: 152188634950 | I6: 1.4021824e+11 | J6: 2.3004975e+11 | K6: 5.4773749e+10 | L6: 56739334938 | M6: 1.3509365e+10 | N6: 391484 | O6: 14338 | P6: 22308747111 | Q6: 6242564037 | R6: 3786737908 | S6: 3985038215 | T6: 7771776123 | U6: 17296133580 | V6: 9812890558 | W6: 239076254150 | X6: 239076254150 | Y6: 3.0735937e+11 | Z6: 95449300012 | AA6: 0.37282242 | AB6: 388748.03
A7: 2006 | B7: economia_total | C7: 3 | D7: Rev.3 | E7: 3.3644282e+11 | G7: 1.3131015e+11 | I7: 1.2042281e+11 | J7: 2.1602e+11 | K7: 5.1433334e+10 | L7: 4.7362257e+10 | M7: 1.1276728e+10 | N7: 205952.96 | P7: 1.915072e+10 | Q7: 1.006294e+10 | R7: 3.231972e+09 | S7: 2.9316136e+09 | T7: 6.1635855e+09 | U7: 1.7116477e+10 | V7: 1.0046136e+10 | W7: 2.316872e+11 | X7: 2.316872e+11 | Y7: 2.9439726e+11 | Z7: 8.3947897e+10 | AA7: 0.36068998 | AB7: 637573.52
A8: 2007 | B8: economia_total | C8: 3 | D8: Rev.3 | E8: 4.8136912e+11 | G8: 1.968987e+11 | I8: 1.8138622e+11 | J8: 2.9998289e+11 | K8: 7.1424499e+10 | L8: 7.5965598e+10 | M8: 1.8087047e+10 | N8: 384437.89 | P8: 3.885926e+10 | Q8: 1.7362443e+10 | R8: 4.047232e+09 | S8: 5.3841649e+09 | T8: 9.4313969e+09 | U8: 2.1950974e+10 | V8: 9.8949244e+09 | W8: 2.9195559e+11 | X8: 2.9195559e+11 | Y8: 3.8146713e+11 | Z8: 1.209331e+11 | AA8: 0.38581056 | AB8: 512172.98
A9: 2008 | B9: economia_total | C9: 4 | D9: Rev.4 | E9: 5.591443e+11 | G9: 2.0589024e+11 | I9: 1.8827405e+11 | J9: 3.7087024e+11 | K9: 8.8302439e+10 | L9: 9.4216384e+10 | M9: 2.2432472e+10 | N9: 436444.3 | P9: 4.3310216e+10 | Q9: 2.6919226e+10 | R9: 9.0138274e+09 | S9: 7.3711258e+09 | T9: 1.6384953e+10 | U9: 2.527665e+10 | V9: 8.1270874e+09 | W9: 3.3345108e+11 | X9: 3.3345108e+11 | Y9: 4.4418599e+11 | Z9: 1.1167385e+11 | AA9: 0.45760491 | AB9: 471744.59
A10: 2009 | B10: economia_total | C10: 4 | D10: Rev.4 | E10: 5.7252529e+11 | G10: 2.346524e+11 | I10: 2.1708145e+11 | J10: 3.5544385e+11 | K10: 8.4629487e+10 | L10: 1.1710891e+11 | M10: 2.7883075e+10 | N10: 477461.01 | P10: 3.7495334e+10 | Q10: 2.1581498e+10 | R10: 9.6793861e+09 | S10: 4.223926e+09 | T10: 1.3903312e+10 | U10: 2.66882e+10 | V10: 8.2255544e+09 | W10: 3.4639399e+11 | X10: 3.4639399e+11 | Y10: 4.5890656e+11 | Z10: 1.1754349e+11 | AA10: 0.499074 | AB10: 491458.78
A11: 2010 | B11: economia_total | C11: 4 | D11: Rev.4 | E11: 7.0942489e+11 | G11: 3.0830526e+11 | I11: 2.8623515e+11 | J11: 4.2318974e+11 | K11: 1.0075946e+11 | L11: 1.4468574e+11 | M11: 3.4448987e+10 | N11: 522282.77 | P11: 6.1076799e+10 | Q11: 3.5070356e+10 | R11: 9.3453961e+09 | S11: 1.4770568e+10 | T11: 2.4115964e+10 | U11: 3.1780277e+10 | V11: 1.1905201e+10 | W11: 4.4909621e+11 | X11: 4.4909621e+11 | Y11: 5.8430465e+11 | Z11: 1.6361952e+11 | AA11: 0.46929379 | AB11: 590303.34
A12: 2011 | B12: economia_total | C12: 4 | D12: Rev.4 | E12: 7.7149858e+11 | G12: 3.2970912e+11 | I12: 3.0649571e+11 | J12: 4.6500287e+11 | K12: 1.1071497e+11 | L12: 1.7297059e+11 | M12: 4.1183474e+10 | N12: 542457.77 | O12: 11157 | U12: 3.1493511e+10 | V12: 2.2457275e+10 | X12: 4.6528233e+11 | Y12: 6.1718078e+11 | Z12: 1.5673853e+11 | AA12: 0.52461573 | AB12: 607806.06
A13: 2012 | B13: economia_total | C13: 4 | D13: Rev.4 | E13: 9.0871608e+11 | G13: 3.8080398e+11 | I13: 3.5443286e+11 | J13: 5.5428322e+11 | K13: 1.319722e+11 | L13: 2.0437987e+11 | M13: 4.8661873e+10 | N13: 564843.8 | P13: 7.0402577e+10 | Q13: 3.9914784e+10 | R13: 1.6418463e+10 | S13: 1.0196186e+10 | T13: 2.6614649e+10 | U13: 3.5113807e+10 | V13: 1.9479252e+10 | W13: 4.9028704e+11 | X13: 4.9028704e+11 | Y13: 6.7092111e+11 | Z13: 1.7642411e+11 | AA13: 0.53670623 | AB13: 674175.73
A14: 2013 | B14: economia_total | C14: 4 | D14: Rev.4 | E14: 1.0296306e+12 | G14: 4.4643853e+11 | I14: 4.1664136e+11 | J14: 6.1298921e+11 | K14: 1.4594981e+11 | L14: 2.3971732e+11 | M14: 5.7075553e+10 | N14: 592299.21 | P14: 9.563226e+10 | Q14: 5.3002735e+10 | R14: 1.4065687e+10 | S14: 2.5576873e+10 | T14: 3.964256e+10 | U14: 3.7001352e+10 | V14: 2.4693359e+10 | W14: 5.5187675e+11 | X14: 5.5187675e+11 | Y14: 7.5490212e+11 | Z14: 2.0672121e+11 | AA14: 0.53695482 | AB14: 753738.19
A15: 2014 | B15: economia_total | C15: 4 | D15: Rev.4 | E15: 1.199314e+12 | G15: 5.2532185e+11 | I15: 4.9047465e+11 | J15: 7.0883934e+11 | K15: 1.6877127e+11 | L15: 2.8092664e+11 | M15: 6.6887294e+10 | N15: 616859.35 | P15: 1.5922797e+11 | Q15: 1.0591236e+11 | R15: 1.6710162e+10 | S15: 6.0562625e+10 | T15: 7.7272787e+10 | U15: 4.4318808e+10 | V15: 2.6736847e+10 | W15: 6.764145e+11 | X15: 6.764145e+11 | Y15: 9.1207306e+11 | Z15: 2.4439521e+11 | AA15: 0.53477051 | AB15: 851607.18
A16: 2015 | B16: economia_total | C16: 4 | D16: Rev.4 | E16: 1.3388148e+12 | G16: 6.0720755e+11 | I16: 5.6711566e+11 | J16: 7.7169915e+11 | K16: 1.8373789e+11 | L16: 3.1807998e+11 | M16: 7.5733327e+10 | N16: 618979.93 | P16: 1.0522485e+11 | Q16: 5.8717066e+10 | R16: 1.2495622e+10 | S16: 1.5923038e+10 | T16: 2.841866e+10 | U16: 5.339056e+10 | V16: 3.5268317e+10 | W16: 7.3606147e+11 | X16: 7.3606147e+11 | Y16: 9.9553269e+11 | Z16: 2.8912757e+11 | AA16: 0.52384062 | AB16: 980980.99
A17: 2016 | B17: economia_total | C17: 4 | D17: Rev.4 | E17: 1.4026078e+12 | G17: 6.5167676e+11 | I17: 6.0988181e+11 | J17: 7.9272596e+11 | K17: 1.8874428e+11 | L17: 3.5093764e+11 | M17: 8.3556581e+10 | N17: 614484.09 | P17: 1.0398437e+11 | Q17: 4.9358984e+10 | R17: 9.7301337e+09 | S17: 1.5913459e+10 | T17: 2.5643593e+10 | U17: 5.4852592e+10 | V17: 4.029588e+10 | W17: 8.0602147e+11 | X17: 8.0602147e+11 | Y17: 1.0783223e+12 | Z17: 3.0073912e+11 | AA17: 0.53851489 | AB17: 1060526.7
