Workbook

Sheet Base
A1: EXPORTACIONES CUMPLIDAS, VALORES CORRIENTES; Empalme Rev 3/Rev4; miles de dólares; BCU | I1: 01. | J1: 0112+0130*+0140*. | K1: 0122 + 0121 + 0130*+0140*+0150. | L1: 02. | N1: 15. | O1: 1511. | P1: 1512. | Q1: 1520. | R1: 1531. | S1: 1553. | T1: Resto 15 (1) | U1: 16. | V1: 17. | W1: 1711 + 1712. | X1: 18. | Y1: 19. | Z1: 1911 + 1912. | AA1: 20. | AB1: 21 + 22. | AC1: 23. | AD1: 24. | AE1: 2411 + 2413. | AF1: 2412 + 2421. | AG1: 2423. | AH1: 2424. | AI1: 25. | AJ1: 26 + 27. | AK1: 34 + 35. | AL1: Resto D (2) | AV1: 15. | AW1: 1511. | AX1: 1512. | AY1: 1520. | AZ1: 1531. | BA1: 1553. | BB1: Resto 15 (1) | BC1: 16. | BD1: 17. | BE1: 18. | BF1: 19. | BG1: 20. | BH1: 21 + 22. | BI1: 23. | BJ1: 24. | BK1: 25. | BL1: 26 + 27. | BM1: 34 + 35. | BN1: Resto D (2)
F2: TOTAL EXPORTACIONES | G2: GRUPO DE PRODUCTOS | H2: ACTIVIDADES PRIMARIAS | I2: Agricultura, Ganadería, Caza y actividades de servicios conexas | J2: Cultivos en general; horticultura; servicios agrícolas aplicados a estos cultivos | K2: Cría de animales; caza ordinaria y servicios conexos; producción de pieles finas mediante actividades de caza ordinaria y con trampas; servicios ganaderos | L2: Silvicultura, extracción de madera y actividades de servicios conexas | M2: INDUSTRIAS MANUFACTURERAS | N2: Elaboración de productos alimenticios y bebidas | O2: Producción, procesamiento y conservación de carne y productos cárnicos | P2: Elaboración y conservación de pescado y productos de pescado | Q2: Elaboración de productos lácteos | R2: Elaboración de arroz y productos derivados del arroz | S2: Elaboración de bebidas malteadas y de malta | T2: Elaboración de productos alimenticios y bebidas - Resto | U2: Elaboración de Productos de Tabaco | V2: Fabricación de productos textiles | W2: Preparación, hilandería, tejeduría y acabado de productos textiles | X2: Fabricación de prendas de vestir; adobo y teñido de pieles | Y2: Curtido y adobo de cueros; fabricación de maletas, bolsos de mano, artículos de talabartería y guarnicionería, y calzado | Z2: Curtido y adobo de cueros; fabricación de maletas, bolsos de mano y artículos de talabartería y guarnicionería | AA2: Producción de madera y fabricación de productos de madera y corcho excepto muebles; fabricación de artículos de paja y de materiales trenzables | AB2: Fabricación de papel y de productos de papel; Actividades de edición e impresión y de reproducción de grabaciones | AC2: Fabricación de coque, productos de la refinación del petróleo y combustible nuclear | AD2: Fabricación de sustancias y productos químicos | AE2: Fabricación de sustancias químicas básicas, excepto abonos y compuestos de nitrógeno; fabricación de plásticos en formas primarias y de caucho sintético | AF2: Fabricación de abonos y compuestos de nitrógeno; Fabricación de plaguicidas y otros productos químicos de uso agropecuario | AG2: Fabricación de productos farmaceúticos, sustancias químicas medicinales y productos botánicos | AH2: Fabricación de jabones y detergentes, preparados para limpiar y pulir, perfumes y preparados de tocador | AI2: Fabricación de productos de caucho y plástico | AJ2: Fabricación de metales comunes; Fabricación de otros productos minerales no metálicos | AK2: Fabricación de vehículos automotores, remolques y semirremolques; Fabricación de otros tipos de equipo de transporte | AL2: INDUSTRIAS MANUFACTURERAS - Resto | AM2: ELECTRICIDAD, GAS Y AGUA | AP2: Total exportaciones | AQ2: Industrias primarias | AR2: Cultivos en general; horticultura; servicios agrícolas aplicados a estos cultivos | AS2: Cría de animales; caza ordinaria y servicios conexos; producción de pieles finas mediante actividades de caza ordinaria y con trampas; servicios ganaderos | AT2: Silvicultura, extracción de madera y actividades de servicios conexas | AU2: Industrias manufactureras | AV2: Elaboración de productos alimenticios y bebidas | AW2: Producción, procesamiento y conservación de carne y productos cárnicos | AX2: Elaboración y conservación de pescado y productos de pescado | AY2: Elaboración de productos lácteos | AZ2: Elaboración de arroz y productos derivados del arroz | BA2: Elaboración de bebidas malteadas y de malta | BB2: Elaboración de productos alimenticios y bebidas - Resto | BC2: Elaboración de Productos de Tabaco | BD2: Fabricación de productos textiles | BE2: Fabricación de prendas de vestir; adobo y teñido de pieles | BF2: Curtido y adobo de cueros; fabricación de maletas, bolsos de mano, artículos de talabartería y guarnicionería, y calzado | BG2: Producción de madera y fabricación de productos de madera y corcho excepto muebles; fabricación de artículos de paja y de materiales trenzables | BH2: Fabricación de papel y de productos de papel; Actividades de edición e impresión y de reproducción de grabaciones | BI2: Fabricación de coque, productos de la refinación del petróleo y combustible nuclear | BJ2: Fabricación de sustancias y productos químicos | BK2: Fabricación de productos de caucho y plástico | BL2: Fabricación de metales comunes; Fabricación de otros productos minerales no metálicos | BM2: Fabricación de vehículos automotores, remolques y semirremolques; Fabricación de otros tipos de equipo de transporte | BN2: INDUSTRIAS MANUFACTURERAS - Resto | BO2: Industria primaria / Total exportaciones | BP2: INDUSTRIAS MANUFACTURERAS / Total exportaciones | BQ2: Elaboración de productos alimenticios y bebidas / total exportaciones | BR2: Elaboración de productos alimenticios y bebidas / total manufactura | BS2: Fabricación de papel y de productos de papel / total manufactura | BT2: Carne / manufactura
A3: =YEAR(C3) -> 2000 | B3: =MONTH(C3) -> 1 | C3: 36526 | D3: miles de dólares | F3: 177304 | H3: 12707 | I3: 8956 | J3: 279 | K3: 8677 | L3: 2782 | M3: 164593 | N3: 84012 | O3: 45732 | P3: 4722 | Q3: 10514 | R3: 14187 | S3: 4087 | T3: 4771 | U3: 4315 | V3: 20132 | W3: 19053 | X3: 4495 | Y3: 15122 | Z3: 14828 | AA3: 555 | AB3: 4863 | AC3: 74 | AD3: 11679 | AE3: 5782 | AF3: 511 | AG3: 2500 | AH3: 549 | AI3: 2780 | AJ3: 5341 | AK3: 5330 | AL3: 5894 | AM3: 0 | AO3: 2000 | AP3: =SUMIF($A$3:$A$501,AO3,F$3:F$501) -> 2302090 | AQ3: =SUMIF($A$3:$A$501,$AO3,H$3:H$501) -> 130899 | AR3: =SUMIF($A$3:$A$501,$AO3,J$3:J$501) -> 41866 | AS3: =SUMIF($A$3:$A$501,$AO3,K$3:K$501) -> 36721 | AT3: =SUMIF($A$3:$A$501,$AO3,L$3:L$501) -> 39733 | AU3: =SUMIF($A$3:$A$501,AO3,M$3:M$501) -> 2161817 | AV3: =SUMIF($A$3:$A$501,$AO3,N$3:N$501) -> 956422 | AW3: =SUMIF($A$3:$A$501,$AO3,O$3:O$501) -> 482487 | AX3: =SUMIF($A$3:$A$501,$AO3,P$3:P$501) -> 102258 | AY3: =SUMIF($A$3:$A$501,$AO3,Q$3:Q$501) -> 129412 | AZ3: =SUMIF($A$3:$A$501,$AO3,R$3:R$501) -> 166527 | BA3: =SUMIF($A$3:$A$501,$AO3,S$3:S$501) -> 45519 | BB3: =SUMIF($A$3:$A$501,$AO3,T$3:T$501) -> 30217 | BC3: =SUMIF($A$3:$A$501,$AO3,U$3:U$501) -> 60062 | BD3: =SUMIF($A$3:$A$501,$AO3,V$3:V$501) -> 204257 | BE3: =SUMIF($A$3:$A$501,$AO3,X$3:X$501) -> 96969 | BF3: =SUMIF($A$3:$A$501,$AO3,Y$3:Y$501) -> 228573 | BG3: =SUMIF($A$3:$A$501,$AO3,AA$3:AA$501) -> 9173 | BH3: =SUMIF($A$3:$A$501,$AO3,AB$3:AB$501) -> 75391 | BI3: =SUMIF($A$3:$A$501,$AO3,AC$3:AC$501) -> 25611 | BJ3: =SUMIF($A$3:$A$501,$AO3,AD$3:AD$501) -> 157873 | BK3: =SUMIF($A$3:$A$501,$AO3,AI$3:AI$501) -> 46776 | BL3: =SUMIF($A$3:$A$501,$AO3,AJ$3:AJ$501) -> 73515 | BM3: =SUMIF($A$3:$A$501,$AO3,AK$3:AK$501) -> 162671 | BN3: =SUMIF($A$3:$A$501,$AO3,AL$3:AL$501) -> 64527 | BO3: =AQ3/$AP3 -> 0.056860939 | BP3: =AU3/$AP3 -> 0.93906711 | BQ3: =AV3/AP3 -> 0.41545813 | BR3: =AV3/AU3 -> 0.4424158 | BS3: =BH3/AU3 -> 0.034873905 | BT3: =AW3/AU3 -> 0.22318587
A4: =YEAR(C4) -> 2000 | B4: =MONTH(C4) -> 2 | C4: 36557 | D4: miles de dólares | F4: 201986 | H4: 9294 | I4: 6973 | J4: 1691 | K4: 5282 | L4: 1122 | M4: 192692 | N4: 90754 | O4: 48021 | P4: 7078 | Q4: 10294 | R4: 21297 | S4: 2692 | T4: 1371 | U4: 5289 | V4: 18905 | W4: 17219 | X4: 7554 | Y4: 15844 | Z4: 15415 | AA4: 947 | AB4: 5315 | AC4: 136 | AD4: 12544 | AE4: 6552 | AF4: 1220 | AG4: 2082 | AH4: 995 | AI4: 4003 | AJ4: 6019 | AK4: 21733 | AL4: 3649 | AM4: 0 | AO4: 2001 | AP4: =SUMIF($A$3:$A$501,AO4,F$3:F$501) -> 2061001 | AQ4: =SUMIF($A$3:$A$501,AO4,H$3:H$501) -> 157398 | AR4: =SUMIF($A$3:$A$501,$AO4,J$3:J$501) -> 72156 | AS4: =SUMIF($A$3:$A$501,$AO4,K$3:K$501) -> 31569 | AT4: =SUMIF($A$3:$A$501,$AO4,L$3:L$501) -> 40360 | AU4: =SUMIF($A$3:$A$501,AO4,M$3:M$501) -> 1894160 | AV4: =SUMIF($A$3:$A$501,$AO4,N$3:N$501) -> 778768 | AW4: =SUMIF($A$3:$A$501,$AO4,O$3:O$501) -> 301023 | AX4: =SUMIF($A$3:$A$501,$AO4,P$3:P$501) -> 89208 | AY4: =SUMIF($A$3:$A$501,$AO4,Q$3:Q$501) -> 130011 | AZ4: =SUMIF($A$3:$A$501,$AO4,R$3:R$501) -> 163703 | BA4: =SUMIF($A$3:$A$501,$AO4,S$3:S$501) -> 55058 | BB4: =SUMIF($A$3:$A$501,$AO4,T$3:T$501) -> 39760 | BC4: =SUMIF($A$3:$A$501,$AO4,U$3:U$501) -> 50408 | BD4: =SUMIF($A$3:$A$501,$AO4,V$3:V$501) -> 206079 | BE4: =SUMIF($A$3:$A$501,$AO4,X$3:X$501) -> 79242 | BF4: =SUMIF($A$3:$A$501,$AO4,Y$3:Y$501) -> 235640 | BG4: =SUMIF($A$3:$A$501,$AO4,AA$3:AA$501) -> 8946 | BH4: =SUMIF($A$3:$A$501,$AO4,AB$3:AB$501) -> 73635 | BI4: =SUMIF($A$3:$A$501,$AO4,AC$3:AC$501) -> 30579 | BJ4: =SUMIF($A$3:$A$501,$AO4,AD$3:AD$501) -> 143864 | BK4: =SUMIF($A$3:$A$501,$AO4,AI$3:AI$501) -> 48018 | BL4: =SUMIF($A$3:$A$501,$AO4,AJ$3:AJ$501) -> 70557 | BM4: =SUMIF($A$3:$A$501,$AO4,AK$3:AK$501) -> 112416 | BN4: =SUMIF($A$3:$A$501,$AO4,AL$3:AL$501) -> 56012 | BO4: =AQ4/$AP4 -> 0.076369686 | BP4: =AU4/AP4 -> 0.91904856 | BQ4: =AV4/AP4 -> 0.37785911 | BR4: =AV4/AU4 -> 0.41114161 | BS4: =BH4/AU4 -> 0.038874752 | BT4: =AW4/AU4 -> 0.15892163
A5: =YEAR(C5) -> 2000 | B5: =MONTH(C5) -> 3 | C5: 36586 | D5: miles de dólares | F5: 185997 | H5: 9429 | I5: 5403 | J5: 2914 | K5: 2489 | L5: 2444 | M5: 176561 | N5: 79890 | O5: 45985 | P5: 9990 | Q5: 9360 | R5: 10666 | S5: 2395 | T5: 1495 | U5: 5947 | V5: 16597 | W5: 13946 | X5: 9786 | Y5: 17532 | Z5: 16907 | AA5: 885 | AB5: 6505 | AC5: 1112 | AD5: 13956 | AE5: 7348 | AF5: 1166 | AG5: 2735 | AH5: 626 | AI5: 3594 | AJ5: 6749 | AK5: 10907 | AL5: 3100 | AM5: 0 | AO5: 2002 | AP5: =SUMIF($A$3:$A$501,AO5,F$3:F$501) -> 1861037 | AQ5: =SUMIF($A$3:$A$501,AO5,H$3:H$501) -> 162095 | AR5: =SUMIF($A$3:$A$501,$AO5,J$3:J$501) -> 88817 | AS5: =SUMIF($A$3:$A$501,$AO5,K$3:K$501) -> 22575 | AT5: =SUMIF($A$3:$A$501,$AO5,L$3:L$501) -> 42553 | AU5: =SUMIF($A$3:$A$501,AO5,M$3:M$501) -> 1693280 | AV5: =SUMIF($A$3:$A$501,$AO5,N$3:N$501) -> 777400 | AW5: =SUMIF($A$3:$A$501,$AO5,O$3:O$501) -> 338775 | AX5: =SUMIF($A$3:$A$501,$AO5,P$3:P$501) -> 98874 | AY5: =SUMIF($A$3:$A$501,$AO5,Q$3:Q$501) -> 126391 | AZ5: =SUMIF($A$3:$A$501,$AO5,R$3:R$501) -> 129809 | BA5: =SUMIF($A$3:$A$501,$AO5,S$3:S$501) -> 49365 | BB5: =SUMIF($A$3:$A$501,$AO5,T$3:T$501) -> 34186 | BC5: =SUMIF($A$3:$A$501,$AO5,U$3:U$501) -> 39741 | BD5: =SUMIF($A$3:$A$501,$AO5,V$3:V$501) -> 200795 | BE5: =SUMIF($A$3:$A$501,$AO5,X$3:X$501) -> 53051 | BF5: =SUMIF($A$3:$A$501,$AO5,Y$3:Y$501) -> 210830 | BG5: =SUMIF($A$3:$A$501,$AO5,AA$3:AA$501) -> 9616 | BH5: =SUMIF($A$3:$A$501,$AO5,AB$3:AB$501) -> 56500 | BI5: =SUMIF($A$3:$A$501,$AO5,AC$3:AC$501) -> 9170 | BJ5: =SUMIF($A$3:$A$501,$AO5,AD$3:AD$501) -> 116382 | BK5: =SUMIF($A$3:$A$501,$AO5,AI$3:AI$501) -> 52529 | BL5: =SUMIF($A$3:$A$501,$AO5,AJ$3:AJ$501) -> 57370 | BM5: =SUMIF($A$3:$A$501,$AO5,AK$3:AK$501) -> 65300 | BN5: =SUMIF($A$3:$A$501,$AO5,AL$3:AL$501) -> 44600 | BO5: =AQ5/$AP5 -> 0.087099289 | BP5: =AU5/AP5 -> 0.90985832 | BQ5: =AV5/AP5 -> 0.4177241 | BR5: =AV5/AU5 -> 0.45910895 | BS5: =BH5/AU5 -> 0.033367193 | BT5: =AW5/AU5 -> 0.20007028
A6: =YEAR(C6) -> 2000 | B6: =MONTH(C6) -> 4 | C6: 36617 | D6: miles de dólares | F6: 178242 | H6: 8486 | I6: 6016 | J6: 3465 | K6: 2551 | L6: 1552 | M6: 169752 | N6: 69188 | O6: 40985 | P6: 7466 | Q6: 7203 | R6: 9770 | S6: 1604 | T6: 2161 | U6: 3927 | V6: 17504 | W6: 14857 | X6: 11002 | Y6: 18211 | Z6: 17073 | AA6: 909 | AB6: 6728 | AC6: 2623 | AD6: 13630 | AE6: 7198 | AF6: 806 | AG6: 2502 | AH6: 668 | AI6: 2962 | AJ6: 5672 | AK6: 13873 | AL6: 3524 | AM6: 0 | AO6: 2003 | AP6: =SUMIF($A$3:$A$501,AO6,F$3:F$501) -> 2208151 | AQ6: =SUMIF($A$3:$A$501,AO6,H$3:H$501) -> 265384 | AR6: =SUMIF($A$3:$A$501,$AO6,J$3:J$501) -> 171102 | AS6: =SUMIF($A$3:$A$501,$AO6,K$3:K$501) -> 40227 | AT6: =SUMIF($A$3:$A$501,$AO6,L$3:L$501) -> 47537 | AU6: =SUMIF($A$3:$A$501,AO6,M$3:M$501) -> 1938851 | AV6: =SUMIF($A$3:$A$501,$AO6,N$3:N$501) -> 952388 | AW6: =SUMIF($A$3:$A$501,$AO6,O$3:O$501) -> 464017 | AX6: =SUMIF($A$3:$A$501,$AO6,P$3:P$501) -> 105883 | AY6: =SUMIF($A$3:$A$501,$AO6,Q$3:Q$501) -> 135638 | AZ6: =SUMIF($A$3:$A$501,$AO6,R$3:R$501) -> 159951 | BA6: =SUMIF($A$3:$A$501,$AO6,S$3:S$501) -> 53825 | BB6: =SUMIF($A$3:$A$501,$AO6,T$3:T$501) -> 33078 | BC6: =SUMIF($A$3:$A$501,$AO6,U$3:U$501) -> 23847 | BD6: =SUMIF($A$3:$A$501,$AO6,V$3:V$501) -> 202342 | BE6: =SUMIF($A$3:$A$501,$AO6,X$3:X$501) -> 61662 | BF6: =SUMIF($A$3:$A$501,$AO6,Y$3:Y$501) -> 228346 | BG6: =SUMIF($A$3:$A$501,$AO6,AA$3:AA$501) -> 24576 | BH6: =SUMIF($A$3:$A$501,$AO6,AB$3:AB$501) -> 51299 | BI6: =SUMIF($A$3:$A$501,$AO6,AC$3:AC$501) -> 30516 | BJ6: =SUMIF($A$3:$A$501,$AO6,AD$3:AD$501) -> 123978 | BK6: =SUMIF($A$3:$A$501,$AO6,AI$3:AI$501) -> 75270 | BL6: =SUMIF($A$3:$A$501,$AO6,AJ$3:AJ$501) -> 63672 | BM6: =SUMIF($A$3:$A$501,$AO6,AK$3:AK$501) -> 37125 | BN6: =SUMIF($A$3:$A$501,$AO6,AL$3:AL$501) -> 63828 | BO6: =AQ6/$AP6 -> 0.12018381 | BP6: =AU6/AP6 -> 0.87804276 | BQ6: =AV6/AP6 -> 0.43130565 | BR6: =AV6/AU6 -> 0.49121258 | BS6: =BH6/AU6 -> 0.026458454 | BT6: =AW6/AU6 -> 0.23932577
A7: =YEAR(C7) -> 2000 | B7: =MONTH(C7) -> 5 | C7: 36647 | D7: miles de dólares | F7: 191487 | H7: 13568 | I7: 7482 | J7: 3696 | K7: 3786 | L7: 5170 | M7: 177601 | N7: 73310 | O7: 42788 | P7: 8307 | Q7: 9506 | R7: 6373 | S7: 3737 | T7: 2599 | U7: 4901 | V7: 22239 | W7: 19252 | X7: 10871 | Y7: 17977 | Z7: 16878 | AA7: 823 | AB7: 6689 | AC7: 2137 | AD7: 13158 | AE7: 6354 | AF7: 1061 | AG7: 2783 | AH7: 746 | AI7: 2524 | AJ7: 5552 | AK7: 12902 | AL7: 4519 | AM7: 314 | AO7: 2004 | AP7: =SUMIF($A$3:$A$501,AO7,F$3:F$501) -> 2937230 | AQ7: =SUMIF($A$3:$A$501,AO7,H$3:H$501) -> 361814 | AR7: =SUMIF($A$3:$A$501,$AO7,J$3:J$501) -> 219104 | AS7: =SUMIF($A$3:$A$501,$AO7,K$3:K$501) -> 76389 | AT7: =SUMIF($A$3:$A$501,$AO7,L$3:L$501) -> 55537 | AU7: =SUMIF($A$3:$A$501,AO7,M$3:M$501) -> 2574731 | AV7: =SUMIF($A$3:$A$501,$AO7,N$3:N$501) -> 1312642 | AW7: =SUMIF($A$3:$A$501,$AO7,O$3:O$501) -> 734505 | AX7: =SUMIF($A$3:$A$501,$AO7,P$3:P$501) -> 126510 | AY7: =SUMIF($A$3:$A$501,$AO7,Q$3:Q$501) -> 174681 | AZ7: =SUMIF($A$3:$A$501,$AO7,R$3:R$501) -> 162890 | BA7: =SUMIF($A$3:$A$501,$AO7,S$3:S$501) -> 73326 | BB7: =SUMIF($A$3:$A$501,$AO7,T$3:T$501) -> 40730 | BC7: =SUMIF($A$3:$A$501,$AO7,U$3:U$501) -> 25925 | BD7: =SUMIF($A$3:$A$501,$AO7,V$3:V$501) -> 199846 | BE7: =SUMIF($A$3:$A$501,$AO7,X$3:X$501) -> 67862 | BF7: =SUMIF($A$3:$A$501,$AO7,Y$3:Y$501) -> 239150 | BG7: =SUMIF($A$3:$A$501,$AO7,AA$3:AA$501) -> 51174 | BH7: =SUMIF($A$3:$A$501,$AO7,AB$3:AB$501) -> 56597 | BI7: =SUMIF($A$3:$A$501,$AO7,AC$3:AC$501) -> 128189 | BJ7: =SUMIF($A$3:$A$501,$AO7,AD$3:AD$501) -> 167553 | BK7: =SUMIF($A$3:$A$501,$AO7,AI$3:AI$501) -> 105039 | BL7: =SUMIF($A$3:$A$501,$AO7,AJ$3:AJ$501) -> 87966 | BM7: =SUMIF($A$3:$A$501,$AO7,AK$3:AK$501) -> 58329 | BN7: =SUMIF($A$3:$A$501,$AO7,AL$3:AL$501) -> 74465 | BO7: =AQ7/$AP7 -> 0.12318205 | BP7: =AU7/AP7 -> 0.87658474 | BQ7: =AV7/AP7 -> 0.44689793 | BR7: =AV7/AU7 -> 0.50981714 | BS7: =BH7/AU7 -> 0.021981714 | BT7: =AW7/AU7 -> 0.28527446
A8: =YEAR(C8) -> 2000 | B8: =MONTH(C8) -> 6 | C8: 36678 | D8: miles de dólares | F8: 199539 | H8: 11416 | I8: 8900 | J8: 5804 | K8: 3096 | L8: 1167 | M8: 186469 | N8: 76312 | O8: 37566 | P8: 10541 | Q8: 11915 | R8: 10241 | S8: 3509 | T8: 2540 | U8: 4654 | V8: 18002 | W8: 15269 | X8: 7815 | Y8: 20858 | Z8: 18595 | AA8: 783 | AB8: 6594 | AC8: 3346 | AD8: 13218 | AE8: 6689 | AF8: 1645 | AG8: 2336 | AH8: 563 | AI8: 3386 | AJ8: 7638 | AK8: 18243 | AL8: 5621 | AM8: 1648 | AO8: 2005 | AP8: =SUMIF($A$3:$A$501,AO8,F$3:F$501) -> 3421893 | AQ8: =SUMIF($A$3:$A$501,AO8,H$3:H$501) -> 338127 | AR8: =SUMIF($A$3:$A$501,$AO8,J$3:J$501) -> 224514 | AS8: =SUMIF($A$3:$A$501,$AO8,K$3:K$501) -> 45623 | AT8: =SUMIF($A$3:$A$501,$AO8,L$3:L$501) -> 56384 | AU8: =SUMIF($A$3:$A$501,AO8,M$3:M$501) -> 3071499 | AV8: =SUMIF($A$3:$A$501,$AO8,N$3:N$501) -> 1618909 | AW8: =SUMIF($A$3:$A$501,$AO8,O$3:O$501) -> 904298 | AX8: =SUMIF($A$3:$A$501,$AO8,P$3:P$501) -> 137808 | AY8: =SUMIF($A$3:$A$501,$AO8,Q$3:Q$501) -> 246135 | AZ8: =SUMIF($A$3:$A$501,$AO8,R$3:R$501) -> 199144 | BA8: =SUMIF($A$3:$A$501,$AO8,S$3:S$501) -> 74566 | BB8: =SUMIF($A$3:$A$501,$AO8,T$3:T$501) -> 56962 | BC8: =SUMIF($A$3:$A$501,$AO8,U$3:U$501) -> 21892 | BD8: =SUMIF($A$3:$A$501,$AO8,V$3:V$501) -> 208651 | BE8: =SUMIF($A$3:$A$501,$AO8,X$3:X$501) -> 66945 | BF8: =SUMIF($A$3:$A$501,$AO8,Y$3:Y$501) -> 247853 | BG8: =SUMIF($A$3:$A$501,$AO8,AA$3:AA$501) -> 85898 | BH8: =SUMIF($A$3:$A$501,$AO8,AB$3:AB$501) -> 68393 | BI8: =SUMIF($A$3:$A$501,$AO8,AC$3:AC$501) -> 150661 | BJ8: =SUMIF($A$3:$A$501,$AO8,AD$3:AD$501) -> 185444 | BK8: =SUMIF($A$3:$A$501,$AO8,AI$3:AI$501) -> 139253 | BL8: =SUMIF($A$3:$A$501,$AO8,AJ$3:AJ$501) -> 111849 | BM8: =SUMIF($A$3:$A$501,$AO8,AK$3:AK$501) -> 70378 | BN8: =SUMIF($A$3:$A$501,$AO8,AL$3:AL$501) -> 95373 | BO8: =AQ8/$AP8 -> 0.09881285 | BP8: =AU8/AP8 -> 0.89760229 | BQ8: =AV8/AP8 -> 0.47310334 | BR8: =AV8/AU8 -> 0.52707457 | BS8: =BH8/AU8 -> 0.022266978 | BT8: =AW8/AU8 -> 0.29441585
A9: =YEAR(C9) -> 2000 | B9: =MONTH(C9) -> 7 | C9: 36708 | D9: miles de dólares | F9: 196148 | H9: 13816 | I9: 7002 | J9: 5097 | K9: 1905 | L9: 5927 | M9: 179086 | N9: 79359 | O9: 34716 | P9: 11526 | Q9: 10571 | R9: 17492 | S9: 2279 | T9: 2775 | U9: 4518 | V9: 14648 | W9: 12035 | X9: 7342 | Y9: 18950 | Z9: 17670 | AA9: 793 | AB9: 7895 | AC9: 2458 | AD9: 11921 | AE9: 5562 | AF9: 1122 | AG9: 3145 | AH9: 674 | AI9: 4002 | AJ9: 5655 | AK9: 16215 | AL9: 5330 | AM9: 3246 | AO9: 2006 | AP9: =SUMIF($A$3:$A$501,AO9,F$3:F$501) -> 3989322 | AQ9: =SUMIF($A$3:$A$501,AO9,H$3:H$501) -> 427489 | AR9: =SUMIF($A$3:$A$501,$AO9,J$3:J$501) -> 246951 | AS9: =SUMIF($A$3:$A$501,$AO9,K$3:K$501) -> 91480 | AT9: =SUMIF($A$3:$A$501,$AO9,L$3:L$501) -> 74569 | AU9: =SUMIF($A$3:$A$501,AO9,M$3:M$501) -> 3559215 | AV9: =SUMIF($A$3:$A$501,$AO9,N$3:N$501) -> 1910907 | AW9: =SUMIF($A$3:$A$501,$AO9,O$3:O$501) -> 1134608 | AX9: =SUMIF($A$3:$A$501,$AO9,P$3:P$501) -> 160679 | AY9: =SUMIF($A$3:$A$501,$AO9,Q$3:Q$501) -> 257017 | AZ9: =SUMIF($A$3:$A$501,$AO9,R$3:R$501) -> 217511 | BA9: =SUMIF($A$3:$A$501,$AO9,S$3:S$501) -> 81144 | BB9: =SUMIF($A$3:$A$501,$AO9,T$3:T$501) -> 59945 | BC9: =SUMIF($A$3:$A$501,$AO9,U$3:U$501) -> 21270 | BD9: =SUMIF($A$3:$A$501,$AO9,V$3:V$501) -> 209476 | BE9: =SUMIF($A$3:$A$501,$AO9,X$3:X$501) -> 67960 | BF9: =SUMIF($A$3:$A$501,$AO9,Y$3:Y$501) -> 301994 | BG9: =SUMIF($A$3:$A$501,$AO9,AA$3:AA$501) -> 115782 | BH9: =SUMIF($A$3:$A$501,$AO9,AB$3:AB$501) -> 72247 | BI9: =SUMIF($A$3:$A$501,$AO9,AC$3:AC$501) -> 138182 | BJ9: =SUMIF($A$3:$A$501,$AO9,AD$3:AD$501) -> 213001 | BK9: =SUMIF($A$3:$A$501,$AO9,AI$3:AI$501) -> 171456 | BL9: =SUMIF($A$3:$A$501,$AO9,AJ$3:AJ$501) -> 145040 | BM9: =SUMIF($A$3:$A$501,$AO9,AK$3:AK$501) -> 112037 | BN9: =SUMIF($A$3:$A$501,$AO9,AL$3:AL$501) -> 79865 | BO9: =AQ9/$AP9 -> 0.10715831 | BP9: =AU9/AP9 -> 0.89218544 | BQ9: =AV9/AP9 -> 0.47900546 | BR9: =AV9/AU9 -> 0.53689002 | BS9: =BH9/AU9 -> 0.020298577 | BT9: =AW9/AU9 -> 0.31878041
A10: =YEAR(C10) -> 2000 | B10: =MONTH(C10) -> 8 | C10: 36739 | D10: miles de dólares | F10: 212700 | H10: 14631 | I10: 9646 | J10: 7641 | K10: 2005 | L10: 3801 | M10: 197942 | N10: 89434 | O10: 41783 | P10: 8887 | Q10: 11501 | R10: 21000 | S10: 3902 | T10: 2360 | U10: 5702 | V10: 16910 | W10: 14202 | X10: 8021 | Y10: 22921 | Z10: 20879 | AA10: 661 | AB10: 6795 | AC10: 2121 | AD10: 13038 | AE10: 5454 | AF10: 2774 | AG10: 2645 | AH10: 861 | AI10: 4869 | AJ10: 6023 | AK10: 15801 | AL10: 5647 | AM10: 119 | AO10: 2007 | AP10: =SUMIF($A$3:$A$501,AO10,F$3:F$501) -> 4517552 | AQ10: =SUMIF($A$3:$A$501,AO10,H$3:H$501) -> 610450 | AR10: =SUMIF($A$3:$A$501,$AO10,J$3:J$501) -> 376553 | AS10: =SUMIF($A$3:$A$501,$AO10,K$3:K$501) -> 107744 | AT10: =SUMIF($A$3:$A$501,$AO10,L$3:L$501) -> 113226 | AU10: =SUMIF($A$3:$A$501,AO10,M$3:M$501) -> 3838735 | AV10: =SUMIF($A$3:$A$501,$AO10,N$3:N$501) -> 1988585 | AW10: =SUMIF($A$3:$A$501,$AO10,O$3:O$501) -> 1014969 | AX10: =SUMIF($A$3:$A$501,$AO10,P$3:P$501) -> 189257 | AY10: =SUMIF($A$3:$A$501,$AO10,Q$3:Q$501) -> 335821 | AZ10: =SUMIF($A$3:$A$501,$AO10,R$3:R$501) -> 278692 | BA10: =SUMIF($A$3:$A$501,$AO10,S$3:S$501) -> 89878 | BB10: =SUMIF($A$3:$A$501,$AO10,T$3:T$501) -> 79970 | BC10: =SUMIF($A$3:$A$501,$AO10,U$3:U$501) -> 21890 | BD10: =SUMIF($A$3:$A$501,$AO10,V$3:V$501) -> 235354 | BE10: =SUMIF($A$3:$A$501,$AO10,X$3:X$501) -> 67272 | BF10: =SUMIF($A$3:$A$501,$AO10,Y$3:Y$501) -> 304703 | BG10: =SUMIF($A$3:$A$501,$AO10,AA$3:AA$501) -> 134537 | BH10: =SUMIF($A$3:$A$501,$AO10,AB$3:AB$501) -> 64114 | BI10: =SUMIF($A$3:$A$501,$AO10,AC$3:AC$501) -> 125794 | BJ10: =SUMIF($A$3:$A$501,$AO10,AD$3:AD$501) -> 272361 | BK10: =SUMIF($A$3:$A$501,$AO10,AI$3:AI$501) -> 207886 | BL10: =SUMIF($A$3:$A$501,$AO10,AJ$3:AJ$501) -> 194523 | BM10: =SUMIF($A$3:$A$501,$AO10,AK$3:AK$501) -> 124999 | BN10: =SUMIF($A$3:$A$501,$AO10,AL$3:AL$501) -> 96715 | BO10: =AQ10/$AP10 -> 0.13512849 | BP10: =AU10/AP10 -> 0.84973787 | BQ10: =AV10/AP10 -> 0.44019084 | BR10: =AV10/AU10 -> 0.51803133 | BS10: =BH10/AU10 -> 0.016701856 | BT10: =AW10/AU10 -> 0.26440194
A11: =YEAR(C11) -> 2000 | B11: =MONTH(C11) -> 9 | C11: 36770 | D11: miles de dólares | F11: 207347 | H11: 9929 | I11: 6877 | J11: 5527 | K11: 1350 | L11: 1873 | M11: 196404 | N11: 85265 | O11: 41309 | P11: 9948 | Q11: 10988 | R11: 17463 | S11: 2972 | T11: 2584 | U11: 5649 | V11: 16174 | W11: 13503 | X11: 10689 | Y11: 21669 | Z11: 21185 | AA11: 875 | AB11: 5982 | AC11: 2150 | AD11: 16298 | AE11: 6398 | AF11: 3327 | AG11: 3537 | AH11: 1191 | AI11: 4079 | AJ11: 7171 | AK11: 14035 | AL11: 6368 | AM11: 979 | AO11: 2008 | AP11: =SUMIF($A$3:$A$501,AO11,F$3:F$501) -> 5941896 | AQ11: =SUMIF($A$3:$A$501,AO11,H$3:H$501) -> 922943 | AR11: =SUMIF($A$3:$A$501,$AO11,J$3:J$501) -> 599442 | AS11: =SUMIF($A$3:$A$501,$AO11,K$3:K$501) -> 132712 | AT11: =SUMIF($A$3:$A$501,$AO11,L$3:L$501) -> 177790 | AU11: =SUMIF($A$3:$A$501,AO11,M$3:M$501) -> 5020585 | AV11: =SUMIF($A$3:$A$501,$AO11,N$3:N$501) -> 2844768 | AW11: =SUMIF($A$3:$A$501,$AO11,O$3:O$501) -> 1487637 | AX11: =SUMIF($A$3:$A$501,$AO11,P$3:P$501) -> 202141 | AY11: =SUMIF($A$3:$A$501,$AO11,Q$3:Q$501) -> 431467 | AZ11: =SUMIF($A$3:$A$501,$AO11,R$3:R$501) -> 441087 | BA11: =SUMIF($A$3:$A$501,$AO11,S$3:S$501) -> 175339 | BB11: =SUMIF($A$3:$A$501,$AO11,T$3:T$501) -> 107095 | BC11: =SUMIF($A$3:$A$501,$AO11,U$3:U$501) -> 19407 | BD11: =SUMIF($A$3:$A$501,$AO11,V$3:V$501) -> 230583 | BE11: =SUMIF($A$3:$A$501,$AO11,X$3:X$501) -> 68214 | BF11: =SUMIF($A$3:$A$501,$AO11,Y$3:Y$501) -> 255033 | BG11: =SUMIF($A$3:$A$501,$AO11,AA$3:AA$501) -> 244424 | BH11: =SUMIF($A$3:$A$501,$AO11,AB$3:AB$501) -> 84894 | BI11: =SUMIF($A$3:$A$501,$AO11,AC$3:AC$501) -> 187209 | BJ11: =SUMIF($A$3:$A$501,$AO11,AD$3:AD$501) -> 375065 | BK11: =SUMIF($A$3:$A$501,$AO11,AI$3:AI$501) -> 247599 | BL11: =SUMIF($A$3:$A$501,$AO11,AJ$3:AJ$501) -> 187281 | BM11: =SUMIF($A$3:$A$501,$AO11,AK$3:AK$501) -> 165588 | BN11: =SUMIF($A$3:$A$501,$AO11,AL$3:AL$501) -> 110516 | BO11: =AQ11/$AP11 -> 0.15532803 | BP11: =AU11/AP11 -> 0.84494663 | BQ11: =AV11/AP11 -> 0.47876435 | BR11: =AV11/AU11 -> 0.56662082 | BS11: =BH11/AU11 -> 0.016909185 | BT11: =AW11/AU11 -> 0.2963075
A12: =YEAR(C12) -> 2000 | B12: =MONTH(C12) -> 10 | C12: 36800 | D12: miles de dólares | F12: 206916 | H12: 11281 | I12: 4697 | J12: 3300 | K12: 1397 | L12: 5649 | M12: 193688 | N12: 82033 | O12: 38259 | P12: 11297 | Q12: 11401 | R12: 10811 | S12: 7489 | T12: 2775 | U12: 5613 | V12: 17520 | W12: 14679 | X12: 8805 | Y12: 21473 | Z12: 20890 | AA12: 698 | AB12: 6086 | AC12: 3436 | AD12: 15159 | AE12: 6930 | AF12: 2575 | AG12: 2811 | AH12: 998 | AI12: 4285 | AJ12: 6223 | AK12: 16853 | AL12: 5505 | AM12: 1937 | AO12: 2009 | AP12: =SUMIF($A$3:$A$501,AO12,F$3:F$501) -> 5404763 | AQ12: =SUMIF($A$3:$A$501,AO12,H$3:H$501) -> 1186044 | AR12: =SUMIF($A$3:$A$501,$AO12,J$3:J$501) -> 826931 | AS12: =SUMIF($A$3:$A$501,$AO12,K$3:K$501) -> 149136 | AT12: =SUMIF($A$3:$A$501,$AO12,L$3:L$501) -> 197544 | AU12: =SUMIF($A$3:$A$501,AO12,M$3:M$501) -> 4214769 | AV12: =SUMIF($A$3:$A$501,$AO12,N$3:N$501) -> 2525679 | AW12: =SUMIF($A$3:$A$501,$AO12,O$3:O$501) -> 1226685 | AX12: =SUMIF($A$3:$A$501,$AO12,P$3:P$501) -> 175320 | AY12: =SUMIF($A$3:$A$501,$AO12,Q$3:Q$501) -> 370626 | AZ12: =SUMIF($A$3:$A$501,$AO12,R$3:R$501) -> 451776 | BA12: =SUMIF($A$3:$A$501,$AO12,S$3:S$501) -> 176437 | BB12: =SUMIF($A$3:$A$501,$AO12,T$3:T$501) -> 124840 | BC12: =SUMIF($A$3:$A$501,$AO12,U$3:U$501) -> 25359 | BD12: =SUMIF($A$3:$A$501,$AO12,V$3:V$501) -> 185074 | BE12: =SUMIF($A$3:$A$501,$AO12,X$3:X$501) -> 49994 | BF12: =SUMIF($A$3:$A$501,$AO12,Y$3:Y$501) -> 167951 | BG12: =SUMIF($A$3:$A$501,$AO12,AA$3:AA$501) -> 137405 | BH12: =SUMIF($A$3:$A$501,$AO12,AB$3:AB$501) -> 117090 | BI12: =SUMIF($A$3:$A$501,$AO12,AC$3:AC$501) -> 75902 | BJ12: =SUMIF($A$3:$A$501,$AO12,AD$3:AD$501) -> 327416 | BK12: =SUMIF($A$3:$A$501,$AO12,AI$3:AI$501) -> 218829 | BL12: =SUMIF($A$3:$A$501,$AO12,AJ$3:AJ$501) -> 147616 | BM12: =SUMIF($A$3:$A$501,$AO12,AK$3:AK$501) -> 133092 | BN12: =SUMIF($A$3:$A$501,$AO12,AL$3:AL$501) -> 103362 | BO12: =AQ12/$AP12 -> 0.21944422 | BP12: =AU12/AP12 -> 0.77982494 | BQ12: =AV12/AP12 -> 0.46730615 | BR12: =AV12/AU12 -> 0.59924494 | BS12: =BH12/AU12 -> 0.027780882 | BT12: =AW12/AU12 -> 0.29104442
A13: =YEAR(C13) -> 2000 | B13: =MONTH(C13) -> 11 | C13: 36831 | D13: miles de dólares | F13: 158951 | H13: 6992 | I13: 3833 | J13: 2278 | K13: 1555 | L13: 2415 | M13: 151485 | N13: 57447 | O13: 23601 | P13: 5722 | Q13: 12546 | R13: 7003 | S13: 5821 | T13: 2753 | U13: 5485 | V13: 12267 | W13: 10639 | X13: 6786 | Y13: 20674 | Z13: 19548 | AA13: 617 | AB13: 4993 | AC13: 4592 | AD13: 13557 | AE13: 7112 | AF13: 1381 | AG13: 2563 | AH13: 521 | AI13: 4727 | AJ13: 6039 | AK13: 8724 | AL13: 5576 | AM13: 474 | AO13: 2010 | AP13: =SUMIF($A$3:$A$501,AO13,F$3:F$501) -> 6724163 | AQ13: =SUMIF($A$3:$A$501,AO13,H$3:H$501) -> 1657363 | AR13: =SUMIF($A$3:$A$501,$AO13,J$3:J$501) -> 1188195 | AS13: =SUMIF($A$3:$A$501,$AO13,K$3:K$501) -> 207795 | AT13: =SUMIF($A$3:$A$501,$AO13,L$3:L$501) -> 249555 | AU13: =SUMIF($A$3:$A$501,AO13,M$3:M$501) -> 4989666 | AV13: =SUMIF($A$3:$A$501,$AO13,N$3:N$501) -> 2799382 | AW13: =SUMIF($A$3:$A$501,$AO13,O$3:O$501) -> 1408775 | AX13: =SUMIF($A$3:$A$501,$AO13,P$3:P$501) -> 188899 | AY13: =SUMIF($A$3:$A$501,$AO13,Q$3:Q$501) -> 520587 | AZ13: =SUMIF($A$3:$A$501,$AO13,R$3:R$501) -> 380045 | BA13: =SUMIF($A$3:$A$501,$AO13,S$3:S$501) -> 151564 | BB13: =SUMIF($A$3:$A$501,$AO13,T$3:T$501) -> 149506 | BC13: =SUMIF($A$3:$A$501,$AO13,U$3:U$501) -> 32508 | BD13: =SUMIF($A$3:$A$501,$AO13,V$3:V$501) -> 243748 | BE13: =SUMIF($A$3:$A$501,$AO13,X$3:X$501) -> 50541 | BF13: =SUMIF($A$3:$A$501,$AO13,Y$3:Y$501) -> 204059 | BG13: =SUMIF($A$3:$A$501,$AO13,AA$3:AA$501) -> 224502 | BH13: =SUMIF($A$3:$A$501,$AO13,AB$3:AB$501) -> 107710 | BI13: =SUMIF($A$3:$A$501,$AO13,AC$3:AC$501) -> 131958 | BJ13: =SUMIF($A$3:$A$501,$AO13,AD$3:AD$501) -> 402798 | BK13: =SUMIF($A$3:$A$501,$AO13,AI$3:AI$501) -> 282568 | BL13: =SUMIF($A$3:$A$501,$AO13,AJ$3:AJ$501) -> 159192 | BM13: =SUMIF($A$3:$A$501,$AO13,AK$3:AK$501) -> 191930 | BN13: =SUMIF($A$3:$A$501,$AO13,AL$3:AL$501) -> 158776 | BO13: =AQ13/$AP13 -> 0.24647871 | BP13: =AU13/AP13 -> 0.74205013 | BQ13: =AV13/AP13 -> 0.4163168 | BR13: =AV13/AU13 -> 0.56103595 | BS13: =BH13/AU13 -> 0.021586615 | BT13: =AW13/AU13 -> 0.28233854
A14: =YEAR(C14) -> 2000 | B14: =MONTH(C14) -> 12 | C14: 36861 | D14: miles de dólares | F14: 185473 | H14: 9350 | I14: 2802 | J14: 174 | K14: 2628 | L14: 5831 | M14: 175544 | N14: 89418 | O14: 41742 | P14: 6774 | Q14: 13613 | R14: 20224 | S14: 5032 | T14: 2033 | U14: 4062 | V14: 13359 | W14: 11955 | X14: 3803 | Y14: 17342 | Z14: 16970 | AA14: 627 | AB14: 6946 | AC14: 1426 | AD14: 9715 | AE14: 5238 | AF14: 476 | AG14: 1918 | AH14: 563 | AI14: 5565 | AJ14: 5433 | AK14: 8055 | AL14: 9794 | AM14: 578 | AO14: 2011 | AP14: =SUMIF($A$3:$A$501,AO14,F$3:F$501) -> 7911751 | AQ14: =SUMIF($A$3:$A$501,AO14,H$3:H$501) -> 1769795 | AR14: =SUMIF($A$3:$A$501,$AO14,J$3:J$501) -> 1236031 | AS14: =SUMIF($A$3:$A$501,$AO14,K$3:K$501) -> 255453 | AT14: =SUMIF($A$3:$A$501,$AO14,L$3:L$501) -> 256007 | AU14: =SUMIF($A$3:$A$501,AO14,M$3:M$501) -> 6140770 | AV14: =SUMIF($A$3:$A$501,$AO14,N$3:N$501) -> 3466607 | AW14: =SUMIF($A$3:$A$501,$AO14,O$3:O$501) -> 1677452 | AX14: =SUMIF($A$3:$A$501,$AO14,P$3:P$501) -> 235148 | AY14: =SUMIF($A$3:$A$501,$AO14,Q$3:Q$501) -> 691951 | AZ14: =SUMIF($A$3:$A$501,$AO14,R$3:R$501) -> 469215 | BA14: =SUMIF($A$3:$A$501,$AO14,S$3:S$501) -> 213026 | BB14: =SUMIF($A$3:$A$501,$AO14,T$3:T$501) -> 179811 | BC14: =SUMIF($A$3:$A$501,$AO14,U$3:U$501) -> 39642 | BD14: =SUMIF($A$3:$A$501,$AO14,V$3:V$501) -> 317404 | BE14: =SUMIF($A$3:$A$501,$AO14,X$3:X$501) -> 61111 | BF14: =SUMIF($A$3:$A$501,$AO14,Y$3:Y$501) -> 231021 | BG14: =SUMIF($A$3:$A$501,$AO14,AA$3:AA$501) -> 265632 | BH14: =SUMIF($A$3:$A$501,$AO14,AB$3:AB$501) -> 120000 | BI14: =SUMIF($A$3:$A$501,$AO14,AC$3:AC$501) -> 57907 | BJ14: =SUMIF($A$3:$A$501,$AO14,AD$3:AD$501) -> 487418 | BK14: =SUMIF($A$3:$A$501,$AO14,AI$3:AI$501) -> 365086 | BL14: =SUMIF($A$3:$A$501,$AO14,AJ$3:AJ$501) -> 200458 | BM14: =SUMIF($A$3:$A$501,$AO14,AK$3:AK$501) -> 309272 | BN14: =SUMIF($A$3:$A$501,$AO14,AL$3:AL$501) -> 219213 | BO14: =AQ14/$AP14 -> 0.22369195 | BP14: =AU14/AP14 -> 0.77615815 | BQ14: =AV14/AP14 -> 0.43815926 | BR14: =AV14/AU14 -> 0.56452318 | BS14: =BH14/AU14 -> 0.019541523 | BT14: =AW14/AU14 -> 0.27316639
A15: =YEAR(C15) -> 2001 | B15: =MONTH(C15) -> 1 | C15: 36892 | D15: miles de dólares | F15: 197756 | H15: 14679 | I15: 10004 | J15: 195 | K15: 9810 | L15: 4083 | M15: 183026 | N15: 93786 | O15: 45239 | P15: 4706 | Q15: 14655 | R15: 17859 | S15: 6482 | T15: 4844 | U15: 5755 | V15: 16669 | W15: 15323 | X15: 4374 | Y15: 18557 | Z15: 18361 | AA15: 529 | AB15: 5886 | AC15: 1051 | AD15: 11501 | AE15: 6927 | AF15: 328 | AG15: 1978 | AH15: 677 | AI15: 4746 | AJ15: 5233 | AK15: 9318 | AL15: 5620 | AM15: 43 | AO15: 2012 | AP15: =SUMIF($A$3:$A$501,AO15,F$3:F$501) -> 8750830 | AQ15: =SUMIF($A$3:$A$501,AO15,H$3:H$501) -> 2517604 | AR15: =SUMIF($A$3:$A$501,$AO15,J$3:J$501) -> 2059739 | AS15: =SUMIF($A$3:$A$501,$AO15,K$3:K$501) -> 163716 | AT15: =SUMIF($A$3:$A$501,$AO15,L$3:L$501) -> 271577 | AU15: =SUMIF($A$3:$A$501,AO15,M$3:M$501) -> 6226526 | AV15: =SUMIF($A$3:$A$501,$AO15,N$3:N$501) -> 3663064 | AW15: =SUMIF($A$3:$A$501,$AO15,O$3:O$501) -> 1804145 | AX15: =SUMIF($A$3:$A$501,$AO15,P$3:P$501) -> 189354 | AY15: =SUMIF($A$3:$A$501,$AO15,Q$3:Q$501) -> 787916 | AZ15: =SUMIF($A$3:$A$501,$AO15,R$3:R$501) -> 521554 | BA15: =SUMIF($A$3:$A$501,$AO15,S$3:S$501) -> 208083 | BB15: =SUMIF($A$3:$A$501,$AO15,T$3:T$501) -> 152013 | BC15: =SUMIF($A$3:$A$501,$AO15,U$3:U$501) -> 36276 | BD15: =SUMIF($A$3:$A$501,$AO15,V$3:V$501) -> 272225 | BE15: =SUMIF($A$3:$A$501,$AO15,X$3:X$501) -> 50909 | BF15: =SUMIF($A$3:$A$501,$AO15,Y$3:Y$501) -> 245164 | BG15: =SUMIF($A$3:$A$501,$AO15,AA$3:AA$501) -> 202086 | BH15: =SUMIF($A$3:$A$501,$AO15,AB$3:AB$501) -> 116870 | BI15: =SUMIF($A$3:$A$501,$AO15,AC$3:AC$501) -> 93345 | BJ15: =SUMIF($A$3:$A$501,$AO15,AD$3:AD$501) -> 534101 | BK15: =SUMIF($A$3:$A$501,$AO15,AI$3:AI$501) -> 378449 | BL15: =SUMIF($A$3:$A$501,$AO15,AJ$3:AJ$501) -> 226082 | BM15: =SUMIF($A$3:$A$501,$AO15,AK$3:AK$501) -> 139826 | BN15: =SUMIF($A$3:$A$501,$AO15,AL$3:AL$501) -> 268136 | BO15: =AQ15/$AP15 -> 0.28769888 | BP15: =AU15/AP15 -> 0.71153548 | BQ15: =AV15/AP15 -> 0.41859618 | BR15: =AV15/AU15 -> 0.5882998 | BS15: =BH15/AU15 -> 0.018769696 | BT15: =AW15/AU15 -> 0.28975146
... A28: =YEAR(C28) -> 2002 | B28: =MONTH(C28) -> 2 | C28: 37288 | D28: miles de dólares | F28: 157947 | H28: 12614 | I28: 5597 | J28: 1647 | K28: 3951 | L28: 6332 | M28: 145333 | N28: 75362 | O28: 35594 | P28: 5916 | Q28: 10079 | R28: 19028 | S28: 1637 | T28: 3108 | U28: 5075 | V28: 15990 | W28: 15434 | X28: 2512 | Y28: 17529 | Z28: 17500 | AA28: 526 | AB28: 3759 | AC28: 807 | AD28: 8890 | AE28: 4574 | AF28: 223 | AG28: 2674 | AH28: 339 | AI28: 3867 | AJ28: 4241 | AK28: 3281 | AL28: 3494 | AM28: 0 | AO28: 2025 | AP28: =SUMIF($A$3:$A$501,AO28,F$3:F$501) -> 11204489 | AQ28: =SUMIF($A$3:$A$501,AO28,H$3:H$501) -> 3573282 | AR28: =SUMIF($A$3:$A$501,$AO28,J$3:J$501) -> 2021950 | AS28: =SUMIF($A$3:$A$501,$AO28,K$3:K$501) -> 483040 | AT28: =SUMIF($A$3:$A$501,$AO28,L$3:L$501) -> 1018698 | AU28: =SUMIF($A$3:$A$501,AO28,M$3:M$501) -> 7548237 | AV28: =SUMIF($A$3:$A$501,$AO28,N$3:N$501) -> 5394734 | AW28: =SUMIF($A$3:$A$501,$AO28,O$3:O$501) -> 3270297 | AX28: =SUMIF($A$3:$A$501,$AO28,P$3:P$501) -> 109526 | AY28: =SUMIF($A$3:$A$501,$AO28,Q$3:Q$501) -> 914700 | AZ28: =SUMIF($A$3:$A$501,$AO28,R$3:R$501) -> 408620 | BA28: =SUMIF($A$3:$A$501,$AO28,S$3:S$501) -> 251100 | BB28: =SUMIF($A$3:$A$501,$AO28,T$3:T$501) -> 440492 | BC28: =SUMIF($A$3:$A$501,$AO28,U$3:U$501) -> 19686 | BD28: =SUMIF($A$3:$A$501,$AO28,V$3:V$501) -> 129867 | BE28: =SUMIF($A$3:$A$501,$AO28,X$3:X$501) -> 7070 | BF28: =SUMIF($A$3:$A$501,$AO28,Y$3:Y$501) -> 103138 | BG28: =SUMIF($A$3:$A$501,$AO28,AA$3:AA$501) -> 351005 | BH28: =SUMIF($A$3:$A$501,$AO28,AB$3:AB$501) -> 38357 | BI28: =SUMIF($A$3:$A$501,$AO28,AC$3:AC$501) -> 6166 | BJ28: =SUMIF($A$3:$A$501,$AO28,AD$3:AD$501) -> 529279 | BK28: =SUMIF($A$3:$A$501,$AO28,AI$3:AI$501) -> 259361 | BL28: =SUMIF($A$3:$A$501,$AO28,AJ$3:AJ$501) -> 84441 | BM28: =SUMIF($A$3:$A$501,$AO28,AK$3:AK$501) -> 430253 | BN28: =SUMIF($A$3:$A$501,$AO28,AL$3:AL$501) -> 194880 | BO28: =AQ28/$AP28 -> 0.31891521 | BP28: =AU28/AP28 -> 0.67367972 | BQ28: =AV28/AP28 -> 0.4814797 | BR28: =AV28/AU28 -> 0.71470119 | BS28: =BH28/AU28 -> 0.005081584 | BT28: =AW28/AU28 -> 0.43325309
A29: =YEAR(C29) -> 2002 | B29: =MONTH(C29) -> 3 | C29: 37316 | D29: miles de dólares | F29: 154108 | H29: 11015 | I29: 8157 | J29: 4809 | K29: 3348 | L29: 1759 | M29: 143081 | N29: 65964 | O29: 35987 | P29: 8092 | Q29: 10882 | R29: 6562 | S29: 2007 | T29: 2434 | U29: 5036 | V29: 16206 | W29: 15714 | X29: 3190 | Y29: 19546 | Z29: 19542 | AA29: 826 | AB29: 4491 | AC29: 1397 | AD29: 9049 | AE29: 5442 | AF29: 687 | AG29: 1583 | AH29: 345 | AI29: 4571 | AJ29: 4750 | AK29: 4337 | AL29: 3719 | AM29: 0
A30: =YEAR(C30) -> 2002 | B30: =MONTH(C30) -> 4 | C30: 37347 | D30: miles de dólares | F30: 143104 | H30: 16434 | I30: 14793 | J30: 11984 | K30: 2808 | L30: 909 | M30: 126379 | N30: 48484 | O30: 23853 | P30: 5484 | Q30: 8589 | R30: 4697 | S30: 3841 | T30: 2020 | U30: 2390 | V30: 18136 | W30: 16726 | X30: 4386 | Y30: 17967 | Z30: 17939 | AA30: 869 | AB30: 5876 | AC30: 2075 | AD30: 10348 | AE30: 6056 | AF30: 230 | AG30: 2781 | AH30: 309 | AI30: 4505 | AJ30: 4238 | AK30: 4385 | AL30: 2720 | AM30: 251 | AW30: Ranking | AX30: miles usd | AY30: codigo | AZ30: nombre
A31: =YEAR(C31) -> 2002 | B31: =MONTH(C31) -> 5 | C31: 37377 | D31: miles de dólares | F31: 189299 | H31: 26147 | I31: 22557 | J31: 20456 | K31: 2101 | L31: 2871 | M31: 162428 | N31: 75345 | O31: 34823 | P31: 8145 | Q31: 14173 | R31: 14221 | S31: 1214 | T31: 2769 | U31: 3007 | V31: 19770 | W31: 18940 | X31: 3635 | Y31: 18468 | Z31: 18415 | AA31: 782 | AB31: 5280 | AC31: 282 | AD31: 11797 | AE31: 6802 | AF31: 677 | AG31: 2535 | AH31: 378 | AI31: 5125 | AJ31: 5927 | AK31: 8119 | AL31: 4893 | AM31: 725 | AW31: 1 | AX31: 4582834 | AY31: 15. | AZ31: Elaboración de productos alimenticios y bebidas
A32: =YEAR(C32) -> 2002 | B32: =MONTH(C32) -> 6 | C32: 37408 | D32: miles de dólares | F32: 177927 | H32: 23083 | I32: 17736 | J32: 16198 | K32: 1538 | L32: 4656 | M32: 153766 | N32: 76976 | O32: 29919 | P32: 13092 | Q32: 11546 | R32: 14639 | S32: 5840 | T32: 1941 | U32: 3631 | V32: 16531 | W32: 15537 | X32: 4592 | Y32: 19641 | Z32: 19636 | AA32: 717 | AB32: 4343 | AC32: 1274 | AD32: 9476 | AE32: 5000 | AF32: 571 | AG32: 2367 | AH32: 172 | AI32: 3475 | AJ32: 4924 | AK32: 5167 | AL32: 3019 | AM32: 1063 | AW32: 2 | AX32: 2552531 | AY32: 1511. | AZ32: Producción, procesamiento y conservación de carne y productos cárnicos
A33: =YEAR(C33) -> 2002 | B33: =MONTH(C33) -> 7 | C33: 37438 | D33: miles de dólares | F33: 148095 | H33: 14372 | I33: 12236 | J33: 11489 | K33: 747 | L33: 1273 | M33: 132936 | N33: 54587 | O33: 25038 | P33: 7792 | Q33: 10862 | R33: 6180 | S33: 2000 | T33: 2715 | U33: 4461 | V33: 13910 | W33: 12962 | X33: 5847 | Y33: 17509 | Z33: 17485 | AA33: 854 | AB33: 5508 | AC33: 1335 | AD33: 11574 | AE33: 5255 | AF33: 1708 | AG33: 2758 | AH33: 242 | AI33: 3028 | AJ33: 4136 | AK33: 6456 | AL33: 3731 | AM33: 741 | AW33: 3 | AX33: 795333 | AY33: 1520. | AZ33: Elaboración de productos lácteos
A34: =YEAR(C34) -> 2002 | B34: =MONTH(C34) -> 8 | C34: 37469 | D34: miles de dólares | F34: 154248 | H34: 11770 | I34: 8724 | J34: 8114 | K34: 610 | L34: 2292 | M34: 141537 | N34: 57362 | O34: 24413 | P34: 12565 | Q34: 8810 | R34: 4439 | S34: 3861 | T34: 3273 | U34: 4703 | V34: 20784 | W34: 19203 | X34: 8248 | Y34: 16927 | Z34: 16856 | AA34: 722 | AB34: 3830 | AC34: 159 | AD34: 10679 | AE34: 4622 | AF34: 2107 | AG34: 2396 | AH34: 318 | AI34: 4059 | AJ34: 3738 | AK34: 5923 | AL34: 4403 | AM34: 938 | AW34: 4 | AX34: 549434 | AY34: 34 + 35. | AZ34: Fabricación de vehículos automotores, remolques y semirremolques; Fabricación de otros tipos de equipo de transporte
A35: =YEAR(C35) -> 2002 | B35: =MONTH(C35) -> 9 | C35: 37500 | D35: miles de dólares | F35: 136752 | H35: 12325 | I35: 8549 | J35: 8035 | K35: 515 | L35: 3130 | M35: 123555 | N35: 53378 | O35: 15962 | P35: 7743 | Q35: 7968 | R35: 13992 | S35: 5851 | T35: 1862 | U35: 3148 | V35: 13932 | W35: 12644 | X35: 5560 | Y35: 15259 | Z35: 15099 | AA35: 1206 | AB35: 5284 | AC35: 62 | AD35: 9239 | AE35: 3569 | AF35: 1535 | AG35: 2306 | AH35: 776 | AI35: 4415 | AJ35: 5676 | AK35: 3007 | AL35: 3389 | AM35: 869 | AW35: 5 | AX35: 497892 | AY35: 24. | AZ35: Fabricación de sustancias y productos químicos
A36: =YEAR(C36) -> 2002 | B36: =MONTH(C36) -> 10 | C36: 37530 | D36: miles de dólares | F36: 144221 | H36: 5177 | I36: 1601 | J36: 1024 | K36: 577 | L36: 3211 | M36: 138731 | N36: 60690 | O36: 21593 | P36: 8719 | Q36: 12752 | R36: 7650 | S36: 4005 | T36: 5972 | U36: 753 | V36: 20543 | W36: 18835 | X36: 4616 | Y36: 15849 | Z36: 15705 | AA36: 690 | AB36: 4070 | AC36: 5 | AD36: 10544 | AE36: 4805 | AF36: 1552 | AG36: 2670 | AH36: 538 | AI36: 4211 | AJ36: 5968 | AK36: 7517 | AL36: 3276 | AM36: 311 | AW36: 6 | AX36: 491198 | AY36: 1531. | AZ36: Elaboración de arroz y productos derivados del arroz
A37: =YEAR(C37) -> 2002 | B37: =MONTH(C37) -> 11 | C37: 37561 | D37: miles de dólares | F37: 157223 | H37: 11596 | I37: 3848 | J37: 2791 | K37: 1057 | L37: 7334 | M37: 145293 | N37: 70385 | O37: 23950 | P37: 7653 | Q37: 13831 | R37: 15461 | S37: 6502 | T37: 2987 | U37: 2189 | V37: 15385 | W37: 14415 | X37: 4295 | Y37: 15543 | Z37: 15465 | AA37: 897 | AB37: 4492 | AC37: 45 | AD37: 9368 | AE37: 3950 | AF37: 1556 | AG37: 2330 | AH37: 852 | AI37: 5414 | AJ37: 5549 | AK37: 5985 | AL37: 5746 | AM37: 334 | AW37: 7 | AX37: 359973 | AY37: Resto 15 (1) | AZ37: Elaboración de productos alimenticios y bebidas - Resto
A38: =YEAR(C38) -> 2002 | B38: =MONTH(C38) -> 12 | C38: 37591 | D38: miles de dólares | F38: 158135 | H38: 10131 | I38: 3561 | J38: 1167 | K38: 2394 | L38: 6136 | M38: 147694 | N38: 71045 | O38: 33146 | P38: 8997 | Q38: 7870 | R38: 9035 | S38: 8722 | T38: 3275 | U38: 2344 | V38: 17775 | W38: 17092 | X38: 2754 | Y38: 18687 | Z38: 18607 | AA38: 738 | AB38: 4047 | AC38: 0 | AD38: 7768 | AE38: 3325 | AF38: 1018 | AG38: 1836 | AH38: 732 | AI38: 5619 | AJ38: 4457 | AK38: 9182 | AL38: 3278 | AM38: 310 | AW38: 8 | AX38: 335572 | AY38: 20. | AZ38: Producción de madera y fabricación de productos de madera y corcho excepto muebles; fabricación de artículos de paja y de materiales trenzables
A39: =YEAR(C39) -> 2003 | B39: =MONTH(C39) -> 1 | C39: 37622 | D39: miles de dólares | F39: 139064 | H39: 7837 | I39: 5993 | J39: 1839 | K39: 4155 | L39: 1537 | M39: 130803 | N39: 66157 | O39: 34173 | P39: 9603 | Q39: 7306 | R39: 9443 | S39: 3611 | T39: 2022 | U39: 1066 | V39: 12719 | W39: 12028 | X39: 2473 | Y39: 18966 | Z39: 18812 | AA39: 849 | AB39: 4122 | AC39: 56 | AD39: 6855 | AE39: 3573 | AF39: 388 | AG39: 1421 | AH39: 673 | AI39: 5525 | AJ39: 6003 | AK39: 1617 | AL39: 4395 | AM39: 423 | AW39: 9 | AX39: 287173 | AY39: 1553. | AZ39: Elaboración de bebidas malteadas y de malta
A40: =YEAR(C40) -> 2003 | B40: =MONTH(C40) -> 2 | C40: 37653 | D40: miles de dólares | F40: 142204 | H40: 11596 | I40: 8672 | J40: 3056 | K40: 5616 | L40: 2641 | M40: 130470 | N40: 64121 | O40: 33834 | P40: 6627 | Q40: 7608 | R40: 7586 | S40: 5956 | T40: 2511 | U40: 1130 | V40: 19868 | W40: 19364 | X40: 2242 | Y40: 14963 | Z40: 14891 | AA40: 1011 | AB40: 3494 | AC40: 36 | AD40: 8772 | AE40: 4154 | AF40: 778 | AG40: 1947 | AH40: 991 | AI40: 4941 | AJ40: 5006 | AK40: 2020 | AL40: 2865 | AM40: 138 | AW40: 10 | AX40: 271223 | AY40: 25. | AZ40: Fabricación de productos de caucho y plástico
A41: =YEAR(C41) -> 2003 | B41: =MONTH(C41) -> 3 | C41: 37681 | D41: miles de dólares | F41: 160273 | H41: 22891 | I41: 16032 | J41: 10447 | K41: 5585 | L41: 6266 | M41: 136513 | N41: 59534 | O41: 34271 | P41: 9901 | Q41: 9799 | R41: 2697 | S41: 908 | T41: 1958 | U41: 1553 | V41: 20747 | W41: 20013 | X41: 2738 | Y41: 21249 | Z41: 21130 | AA41: 828 | AB41: 3777 | AC41: 208 | AD41: 8669 | AE41: 5108 | AF41: 420 | AG41: 1395 | AH41: 1008 | AI41: 6434 | AJ41: 5028 | AK41: 2235 | AL41: 3513 | AM41: 850 | AW41: 11 | AX41: 216778 | AY41: Resto D (2) | AZ41: INDUSTRIAS MANUFACTURERAS - Resto
A42: =YEAR(C42) -> 2003 | B42: =MONTH(C42) -> 4 | C42: 37712 | D42: miles de dólares | F42: 170126 | H42: 28097 | I42: 27523 | J42: 21839 | K42: 5684 | L42: 65 | M42: 141685 | N42: 66740 | O42: 29039 | P42: 7872 | Q42: 7592 | R42: 14448 | S42: 4853 | T42: 2936 | U42: 1253 | V42: 20599 | W42: 19370 | X42: 3928 | Y42: 18336 | Z42: 18266 | AA42: 1211 | AB42: 4044 | AC42: 826 | AD42: 8916 | AE42: 4240 | AF42: 680 | AG42: 1851 | AH42: 1264 | AI42: 4883 | AJ42: 5461 | AK42: 2333 | AL42: 3155 | AM42: 345 | AW42: 12 | AX42: 147580 | AY42: 19. | AZ42: Curtido y adobo de cueros; fabricación de maletas, bolsos de mano, artículos de talabartería y guarnicionería, y calzado
... A49: =YEAR(C49) -> 2003 | B49: =MONTH(C49) -> 11 | C49: 37926 | D49: miles de dólares | F49: 202299 | H49: 6664 | I49: 3401 | J49: 2978 | K49: 423 | L49: 2577 | M49: 195441 | N49: 109746 | O49: 56544 | P49: 8345 | Q49: 16930 | R49: 17460 | S49: 7323 | T49: 3145 | U49: 2382 | V49: 15108 | W49: 13978 | X49: 5103 | Y49: 18114 | Z49: 17935 | AA49: 802 | AB49: 4613 | AC49: 5699 | AD49: 11222 | AE49: 5290 | AF49: 1034 | AG49: 2993 | AH49: 1076 | AI49: 8012 | AJ49: 5448 | AK49: 3942 | AL49: 5249 | AM49: 179 | AW49: 19 | AX49: 228 | AY49: 23. | AZ49: Fabricación de coque, productos de la refinación del petróleo y combustible nuclear
A50: =YEAR(C50) -> 2003 | B50: =MONTH(C50) -> 12 | C50: 37956 | D50: miles de dólares | F50: 187482 | H50: 10839 | I50: 7312 | J50: 992 | K50: 6320 | L50: 2758 | M50: 176402 | N50: 91731 | O50: 49223 | P50: 5795 | Q50: 12979 | R50: 18699 | S50: 1088 | T50: 3948 | U50: 2379 | V50: 14469 | W50: 13571 | X50: 3925 | Y50: 19704 | Z50: 19488 | AA50: 4273 | AB50: 4361 | AC50: 1481 | AD50: 11346 | AE50: 4519 | AF50: 2132 | AG50: 2356 | AH50: 1385 | AI50: 5765 | AJ50: 5290 | AK50: 3505 | AL50: 8172 | AM50: 235
A51: =YEAR(C51) -> 2004 | B51: =MONTH(C51) -> 1 | C51: 37987 | D51: miles de dólares | F51: 197231 | H51: 15823 | I51: 8386 | J51: 821 | K51: 7565 | L51: 6837 | M51: 181390 | N51: 91019 | O51: 54067 | P51: 7979 | Q51: 9277 | R51: 7575 | S51: 10076 | T51: 2045 | U51: 1757 | V51: 17843 | W51: 16529 | X51: 2137 | Y51: 20576 | Z51: 20358 | AA51: 737 | AB51: 4110 | AC51: 10092 | AD51: 11852 | AE51: 4192 | AF51: 1442 | AG51: 3962 | AH51: 1397 | AI51: 7698 | AJ51: 5951 | AK51: 2536 | AL51: 5083 | AM51: 13
A52: =YEAR(C52) -> 2004 | B52: =MONTH(C52) -> 2 | C52: 38018 | D52: miles de dólares | F52: 179323 | H52: 11974 | I52: 9484 | J52: 3231 | K52: 6253 | L52: 1960 | M52: 167345 | N52: 77671 | O52: 54276 | P52: 7234 | Q52: 7076 | R52: 1715 | S52: 1781 | T52: 5590 | U52: 1504 | V52: 16993 | W52: 15492 | X52: 4015 | Y52: 17284 | Z52: 17230 | AA52: 3960 | AB52: 3878 | AC52: 12042 | AD52: 9969 | AE52: 4285 | AF52: 431 | AG52: 2653 | AH52: 1466 | AI52: 7164 | AJ52: 5728 | AK52: 2974 | AL52: 4164 | AM52: 0
A53: =YEAR(C53) -> 2004 | B53: =MONTH(C53) -> 3 | C53: 38047 | D53: miles de dólares | F53: 213767 | H53: 18863 | I53: 13992 | J53: 5414 | K53: 8578 | L53: 3928 | M53: 194872 | N53: 97028 | O53: 59543 | P53: 11325 | Q53: 13125 | R53: 2514 | S53: 7090 | T53: 3431 | U53: 2491 | V53: 15191 | W53: 13509 | X53: 3665 | Y53: 22814 | Z53: 22579 | AA53: 3224 | AB53: 5531 | AC53: 8605 | AD53: 11031 | AE53: 5634 | AF53: 718 | AG53: 1935 | AH53: 1558 | AI53: 8247 | AJ53: 7249 | AK53: 3279 | AL53: 6517 | AM53: 0
A54: =YEAR(C54) -> 2004 | B54: =MONTH(C54) -> 4 | C54: 38078 | D54: miles de dólares | F54: 224250 | H54: 34825 | I54: 28923 | J54: 15040 | K54: 13882 | L54: 5132 | M54: 189424 | N54: 91093 | O54: 55153 | P54: 9263 | Q54: 10911 | R54: 12422 | S54: 1162 | T54: 2182 | U54: 790 | V54: 17282 | W54: 15746 | X54: 4870 | Y54: 19716 | Z54: 19624 | AA54: 1592 | AB54: 5157 | AC54: 12871 | AD54: 12132 | AE54: 5139 | AF54: 969 | AG54: 3291 | AH54: 1656 | AI54: 8451 | AJ54: 7010 | AK54: 3070 | AL54: 5390 | AM54: 0
A55: =YEAR(C55) -> 2004 | B55: =MONTH(C55) -> 5 | C55: 38108 | D55: miles de dólares | F55: 279176 | H55: 73018 | I55: 68071 | J55: 62126 | K55: 5945 | L55: 3905 | M55: 206141 | N55: 101018 | O55: 55463 | P55: 8715 | Q55: 11787 | R55: 16614 | S55: 5533 | T55: 2905 | U55: 3135 | V55: 17926 | W55: 16281 | X55: 4807 | Y55: 21215 | Z55: 21071 | AA55: 3264 | AB55: 5140 | AC55: 12594 | AD55: 12526 | AE55: 4660 | AF55: 1278 | AG55: 3472 | AH55: 1847 | AI55: 6613 | AJ55: 7007 | AK55: 4599 | AL55: 6297 | AM55: 0
A56: =YEAR(C56) -> 2004 | B56: =MONTH(C56) -> 6 | C56: 38139 | D56: miles de dólares | F56: 248580 | H56: 36680 | I56: 29567 | J56: 24040 | K56: 5527 | L56: 5874 | M56: 211864 | N56: 109804 | O56: 64126 | P56: 12272 | Q56: 15108 | R56: 13462 | S56: 2481 | T56: 2354 | U56: 2404 | V56: 18402 | W56: 16526 | X56: 5995 | Y56: 21741 | Z56: 21575 | AA56: 4283 | AB56: 4735 | AC56: 6216 | AD56: 12240 | AE56: 4186 | AF56: 1803 | AG56: 3431 | AH56: 1863 | AI56: 7396 | AJ56: 7208 | AK56: 5344 | AL56: 6095 | AM56: 0
A57: =YEAR(C57) -> 2004 | B57: =MONTH(C57) -> 7 | C57: 38169 | D57: miles de dólares | F57: 272953 | H57: 53372 | I57: 50472 | J57: 40516 | K57: 9956 | L57: 1798 | M57: 219570 | N57: 105968 | O57: 62537 | P57: 12164 | Q57: 12443 | R57: 7629 | S57: 7394 | T57: 3801 | U57: 2601 | V57: 16163 | W57: 13564 | X57: 8104 | Y57: 18931 | Z57: 18806 | AA57: 4789 | AB57: 4980 | AC57: 17043 | AD57: 14555 | AE57: 5171 | AF57: 3017 | AG57: 3323 | AH57: 1891 | AI57: 8175 | AJ57: 7547 | AK57: 4674 | AL57: 6042 | AM57: 0
A58: =YEAR(C58) -> 2004 | B58: =MONTH(C58) -> 8 | C58: 38200 | D58: miles de dólares | F58: 247027 | H58: 33895 | I58: 26799 | J58: 25753 | K58: 1046 | L58: 5897 | M58: 213124 | N58: 107963 | O58: 53435 | P58: 11761 | Q58: 15560 | R58: 15701 | S58: 8753 | T58: 2753 | U58: 2534 | V58: 15814 | W58: 13262 | X58: 8527 | Y58: 18366 | Z58: 18117 | AA58: 7098 | AB58: 4914 | AC58: 4305 | AD58: 15890 | AE58: 5978 | AF58: 2487 | AG58: 4383 | AH58: 1767 | AI58: 8641 | AJ58: 7907 | AK58: 4840 | AL58: 6326 | AM58: 0
...

Sheet Análisis

Sheet Gráficos
A1: Análisis
A2: Pérdida de peso de las manufacturas en las exportaciones totales y creciente concentración en alimentos y bebidas, que alcanzan el 71% del total manufacturero en 2025.
A3: Crecimiento de largo plazo de las exportaciones industriales, con fuertes oscilaciones y recuperación en 2025 hasta niveles cercanos al máximo de 2022.
A4: Predominio de la carne en las exportaciones alimenticias, seguida a distancia por los lácteos, mientras los demás rubros mantienen una participación menor.
A5: Exportaciones primarias dominadas por los cultivos y sujetas a fuertes variaciones, frente al crecimiento más estable de la silvicultura.
A6: Una devaluación hasta la paridad no aumentaría las exportaciones en dólares si se mantienen precios y cantidades, pero elevaría los ingresos en pesos del sector exportador; en 2023, el incremento sería del 55%.

Sheet Eventual devaluación
A1: Escenario de las exportaciones frente a eventual devaluación, con precios y cantidades exportadas constantes
B4: Expo manuf, miles usd | C4: Ajuste de total manufactura a eaae a partir de microdatos (95%) | D4: TCC ($/USD) | E4: TCP ($/USD) | F4: val_tcp | G4: Situación actual. Pesos apropiados por sector exportador. Miles de pesos recibidos al TCC | H4: Escenario de devaluación. Miles de pesos recibidos al TCP | I4: Incremento para el exportador: Diferencia apropiada por el exportador frente a eventual devaluación | J4: Incremento de apropiación en relación a exportaciones efectivas
A5: 2000 | B5: =Base!$AU3 -> 2161817 | C5: =B5*0.95 -> 2053726.1 | D5: 12.114925 | E5: 17.830572 | F5: 1.4717856 | G5: =C5*D5 -> 24880738 | H5: =C5*E5 -> 36619112 | I5: =H5-G5 -> 11738374 | J5: =I5/G5 -> 0.47178559
A6: 2001 | B6: =Base!$AU4 -> 1894160 | C6: =B6*0.95 -> 1799452 | D6: 13.408852 | E6: 19.078999 | F6: 1.422866 | G6: =C6*D6 -> 24128586 | H6: =C6*E6 -> 34331743 | I6: =H6-G6 -> 10203157 | J6: =I6/G6 -> 0.42286595
A7: 2002 | B7: =Base!$AU5 -> 1693280 | C7: =B7*0.95 -> 1608616 | D7: 21.587268 | E7: 22.652647 | F7: 1.0493522 | G7: =C7*D7 -> 34725625 | H7: =C7*E7 -> 36439410 | I7: =H7-G7 -> 1713785.7 | J7: =I7/G7 -> 0.049352192
A8: 2003 | B8: =Base!$AU6 -> 1938851 | C8: =B8*0.95 -> 1841908.4 | D8: 28.369939 | E8: 26.367312 | F8: 0.92941025 | G8: =C8*D8 -> 52254830 | H8: =C8*E8 -> 48566175 | I8: =H8-G8 -> -3688655.6 | J8: =I8/G8 -> -0.070589753
A9: 2004 | B9: =Base!$AU7 -> 2574731 | C9: =B9*0.95 -> 2445994.4 | D9: 28.703792 | E9: 29.122846 | F9: 1.0145993 | G9: =C9*D9 -> 70209316 | H9: =C9*E9 -> 71234320 | I9: =H9-G9 -> 1025003.8 | J9: =I9/G9 -> 0.014599256
A10: 2005 | B10: =Base!$AU8 -> 3071499 | C10: =B10*0.95 -> 2917924 | D10: 24.478579 | E10: 28.325217 | F10: 1.157143 | G10: =C10*D10 -> 71426634 | H10: =C10*E10 -> 82650832 | I10: =H10-G10 -> 11224198 | J10: =I10/G10 -> 0.15714303
A11: 2006 | B11: =Base!$AU9 -> 3559215 | C11: =B11*0.95 -> 3381254.2 | D11: 24.073374 | E11: 29.954262 | F11: 1.2442901 | G11: =C11*D11 -> 81398198 | H11: =C11*E11 -> 1.0128298e+08 | I11: =H11-G11 -> 19884778 | J11: =I11/G11 -> 0.24429014
A12: 2007 | B12: =Base!$AU10 -> 3838735 | C12: =B12*0.95 -> 3646798.2 | D12: 23.471036 | E12: 30.861639 | F12: 1.3148818 | G12: =C12*D12 -> 85594133 | H12: =C12*E12 -> 1.1254617e+08 | I12: =H12-G12 -> 26952038 | J12: =I12/G12 -> 0.31488184
A13: 2008 | B13: =Base!$AU11 -> 5020585 | C13: =B13*0.95 -> 4769555.8 | D13: 20.949345 | E13: 30.471964 | F13: 1.4545545 | G13: =C13*D13 -> 99919069 | H13: =C13*E13 -> 1.4533773e+08 | I13: =H13-G13 -> 45418662 | J13: =I13/G13 -> 0.4545545
A14: 2009 | B14: =Base!$AU12 -> 4214769 | C14: =B14*0.95 -> 4004030.5 | D14: 22.567971 | E14: 32.276463 | F14: 1.430189 | G14: =C14*D14 -> 90362845 | H14: =C14*E14 -> 1.2923594e+08 | I14: =H14-G14 -> 38873099 | J14: =I14/G14 -> 0.43018896
A15: 2010 | B15: =Base!$AU13 -> 4989666 | C15: =B15*0.95 -> 4740182.7 | D15: 20.059238 | E15: 32.828748 | F15: 1.63659 | G15: =C15*D15 -> 95084453 | H15: =C15*E15 -> 1.5561426e+08 | I15: =H15-G15 -> 60529810 | J15: =I15/G15 -> 0.63658998
A16: 2011 | B16: =Base!$AU14 -> 6140770 | C16: =B16*0.95 -> 5833731.5 | D16: 19.314209 | E16: 34.651025 | F16: 1.7940691 | G16: =C16*D16 -> 1.1267391e+08 | H16: =C16*E16 -> 2.0214478e+08 | I16: =H16-G16 -> 89470867 | J16: =I16/G16 -> 0.79406907
... A29: 2024 | B29: =Base!$AU27 -> 6844958 | C29: =B29*0.95 -> 6502710.1 | D29: 40.235 | E29: 61.848214 | F29: 1.5371744 | G29: =C29*D29 -> 2.6163654e+08 | H29: =C29*E29 -> 4.0218101e+08 | I29: =H29-G29 -> 1.4054446e+08 | J29: =I29/G29 -> 0.53717445

Sheet Exp-VBP
C1: PRODUCCION
C2: POR INDUSTRIAS
C3: Serie anual, precios corrientes
C4: Miles de pesos
B10: 2005 | C10: 2006 | D10: 2007 | E10: 2008 | F10: 2009 | G10: 2010 | H10: 2011 | I10: 2012 | J10: 2013 | K10: 2014 | L10: 2015 | M10: 2016 | N10: 2017* | O10: 2018* | P10: 2019*
A11: Ind. Manufcatura | B11: 2.0518204e+08 | C11: 2.3074232e+08 | D11: 2.5175441e+08 | E11: 3.1759471e+08 | F11: 2.9707791e+08 | G11: 3.1632322e+08 | H11: 3.5982239e+08 | I11: 3.9149387e+08 | J11: 4.1395369e+08 | K11: 4.7121546e+08 | L11: 5.0766251e+08 | M11: 5.3018192e+08 | N11: 5.1623889e+08 | O11: 5.824472e+08 | P11: 6.2485218e+08
A12: expo manuf pesos | C12: 85777081500 | D12: 90210272500 | E12: 104930226500 | F12: 95253779400 | G12: 100292286600 | H12: 118516861000 | I12: 126398477800 | J12: 126463147000 | K12: 145820839200 | L12: 148318361100 | M12: 150663602200 | N12: 153149284400 | O12: 173974169600 | P12: 193535850600
A13: expo manuf miles de pesos | C13: =C12/1000 -> 85777082 | D13: =D12/1000 -> 90210272 | E13: =E12/1000 -> 1.0493023e+08 | F13: =F12/1000 -> 95253779 | G13: =G12/1000 -> 1.0029229e+08 | H13: =H12/1000 -> 118516861 | I13: =I12/1000 -> 1.2639848e+08 | J13: =J12/1000 -> 126463147 | ... P13: =P12/1000 -> 1.9353585e+08
C14: =C13/C11 -> 0.37174404 | D14: =D13/D11 -> 0.35832648 | E14: =E13/E11 -> 0.33039035 | F14: =F13/F11 -> 0.32063568 | G14: =G13/G11 -> 0.31705636 | H14: =H13/H11 -> 0.32937601 | I14: =I13/I11 -> 0.32286196 | J14: =J13/J11 -> 0.30550071 | ... P14: =P13/P11 -> 0.30973062
